Workbook

Sheet 📋使い方ガイド
A1: 有限会社 東輝 給与管理システム 使い方ガイド
A2: ★ このガイドを読めば経理未経験でも給与計算ができます。【黄色セル】＝毎月手入力が必要な箇所です。
A4: ■ シート構成と役割
A5: No | B5: シート名 | C5: 役割・説明 | D5: 編集頻度 | E5: 注意事項
A6: ① | B6: 従業員マスタ | C6: 従業員の基本情報（氏名・雇用区分・日給単価・各種保険料・税額）を管理。全ての給与計算のもとになる重要データ。 | D6: 入退社・保険料改定時 | E6: ★社員IDは「EMP001」形式で統一。変更不可。
A7: ② | B7: 現場マスタ | C7: 現場コード（A〜J等）と現場名・発注者・工事種別を管理。出退勤入力の現場コードと対応する。 | D7: 新工事着工時 | E7: ★コードはアルファベット大文字1文字のみ。
A8: ③ | B8: 出退勤入力 | C8: 毎日の出退勤を1行1件で入力。社員ID・出勤区分・現場・時刻・残業時間を入力すると氏名・現場名が自動表示される。 | D8: 毎日（勤務発生ごと） | E8: ★社員IDは従業員マスタと完全一致させること。
A9: ④ | B9: 月次集計 | C9: 年・月を入力するだけで全員の出勤日数・残業時間・現場別日数・実働時間が自動集計される。給与計算の元データ。 | D9: 月初に年月を更新するだけ | E9: ★E2に年、F2に月を入力するだけ。他は触らない。
A10: ⑤ | B10: 給与計算 | C10: 月次集計・従業員マスタと連動して基本給・残業手当・各種控除・手取金額を自動計算。 ★手当（J列）と立替金（S列）のみ毎月手入力。 | D10: 月1回（月次集計更新後） | E10: ★J列（手当）とS列（立替金）のみ毎月確認・入力。
A11: ⑥ | B11: 出勤簿（印刷用） | C11: カレンダー形式で月次の出勤状況を表示・印刷。保管用として使用。 | D11: 月1回（印刷・保管） | E11: ★印刷後は担当者が押印して保管。
A13: ■ 毎月の作業手順（詳細版）
A14: STEP | B14: 作業内容 | C14: 具体的な操作手順 | D14: 対象シート | E14: チェックポイント
A15: STEP 1 | B15: 年月を設定する | C15: 月次集計シートのE2セルに年（例：2026）、F2セルに月（例：5）を数字で入力する。 | D15: 月次集計 | E15: C2セルに「2026-05-01」と自動表示されれば正常。集計結果が当月のものになっているか確認。
A16: STEP 2 | B16: 出退勤データを 入力する | C16: 出退勤入力シートに当月の出退勤を1行1件で入力（行を追加しながら入力する）。 ★B列：社員ID（EMP001形式） ★E列：出勤区分（○/△/出/有給/欠勤） ★F列：現場コード（A〜J） ★H列：出勤時刻（例：08:00） ★I列：退勤時刻（例：17:00） ★J列：残業時間（h）を手入力 | D16: 出退勤入力 | E16: 氏名（C列）と現場名（G列）が自動で表示されれば入力OK。社員IDが間違えると名前が出ない。外注は名前のみ入力可（社員IDなしでOK）。
A17: STEP 3 | B17: 月次集計を 確認する | C17: 月次集計シートで各人の集計結果を確認する。 ・C列：出勤日数が合っているか ・H列：残業時間が合っているか ・T列：実働時間合計（時給社員の給与計算に使用）が正しいか | D17: 月次集計 | E17: ★時給社員のT列（実働時間合計）が0の場合は出退勤入力にH・I列（時刻）が入力されているか確認。全員が0の場合は年月の設定を確認。
A18: STEP 4 | B18: 給与計算を 確認・調整する | C18: 給与計算シートで各人の給与額を確認し、必要な手入力を行う。 ★J列（手当合計）：現場手当・特別手当・実習生の割増手当などを毎月確認して入力 ★S列（立替金）：個人立替分があれば入力（通常は0円） → T列（手取金額）が最終的な支払金額 | D18: 給与計算 | E18: 手取金額（T列）がマイナスになっていないか確認。時給社員が0円のままなら月次集計T列を確認。実習生の割増手当・休業手当の入力漏れに注意。
A19: STEP 5 | B19: 出勤簿を印刷する | C19: 出勤簿（印刷用）シートを印刷して押印後に保管する。 | D19: 出勤簿（印刷用） | E19: 月次と同じ年月のデータが表示されているか確認。印刷後に担当者が署名・押印して保管。
A21: ■ 雇用区分別 給与計算ロジック
A22: 雇用区分 | B22: 基本給の計算方法 | C22: 残業手当の計算 | D22: 特記事項・注意点 | E22: 担当者の作業
A23: 月給制 （社長・役員・ 正社員） | B23: マスタF列の月額固定給をそのまま支給。出勤日数に関係なく毎月同額。 | C23: 時間単価（マスタG列）×残業時間×1.25倍。 | D23: 欠勤控除がある場合は「月給÷所定労働日数×欠勤日数」の金額をJ列でマイナス入力する。 | E23: J列（手当・控除）のみ毎月確認
A24: 日給制 （日雇・一般作業員） | B24: 日給単価×出勤日数（半日「△」は0.5日扱い）。出勤しなければ基本給なし。 | C24: 時間単価（マスタG列）×残業時間×1.25倍。（時間単価＝日給÷8時間） | D24: 休日出勤（「出」区分）は日給×1.35倍以上をJ列に手入力する。現場手当もJ列。 | E24: J列（手当）を毎月入力
A25: 時給制 （パート・事務員） | B25: 時給単価（マスタG列）×実働時間合計（月次集計T列の自動計算値）。 出退勤時刻から実働時間を自動計算（6h以上は休憩1h控除）。 | C25: 法定労働時間超過分が残業。J列の残業時間に基づき時給×1.25で計算。 | D25: ★出退勤時刻（H・I列）の入力が必須！入力がないと給与が0円になる。 | E25: J列（残業時間）の確認
A26: 実習生 （技能実習生） | B26: 月給制と同じ計算式。ただし最低賃金以上であることを毎月必ず確認する。（熊本県952円/h〜） | C26: 月給制と同じ（時間単価×残業時間×1.25）。深夜（22時〜）は×1.5。法定休日は×1.35。 | D26: ★本人都合欠勤→J列でマイナス入力（欠勤控除） ★会社都合欠勤→J列に休業手当（平均賃金×60%以上）を入力（労基法の義務） ★割増手当（残業・休日）は全てJ列で計算・入力する | E26: ★J列（割増手当・欠勤控除）を毎月必ず計算して入力する
A28: ■ 控除項目の説明と更新タイミング
A29: 控除項目 | B29: 計算方法 | C29: 説明・根拠 | D29: 更新タイミング | E29: マスタ更新箇所
A30: 健康保険料 | B30: マスタH列の 固定月額 | C30: 協会けんぽ等からの通知書に基づく。毎年3月に標準報酬月額に基づく改定あり。 | D30: 毎年3月（改定通知後） | E30: H列を新金額に更新
A31: 厚生年金保険料 | B31: マスタI列の 固定月額 | C31: 毎年9月の標準報酬月額改定時に変わる場合あり。昇降給時は随時改定も必要。 | D31: 毎年9月・昇降給時 | E31: I列を新金額に更新
A32: 雇用保険料 | B32: 総支給額× マスタJ列の率（0.006） | C32: 令和6年度の労働者負担率は6/1000。役員・家族従業員は適用外（J列=0）。 | D32: 毎年4月（年度確認） | E32: J列の率を確認
A33: 所得税（源泉） | B33: マスタK列の 固定月額 | C33: 国税庁の源泉徴収税額表に基づく。年末調整で過不足を精算する。 | D33: 給与額変更時・年末調整 | E33: K列を更新
A34: 住民税 | B34: マスタL列の 固定月額 | C34: ★毎年5〜6月に市区町村から「特別徴収税額の決定通知書」が届く。6月分から新金額を適用。 | D34: ★毎年6月（通知書受取後） | E34: ★L列を新金額に更新
A35: 友愛会費 | B35: マスタM列の 固定月額（通常3000円） | C35: 会社の福利厚生費。役員・パート・実習生は対象外の場合あり（M列を0に設定）。 | D35: 変更時のみ | E35: M列を変更
A36: 立替金 | B36: 給与計算S列 ★手動入力 | C36: 個人が立替えた費用（ガソリン代・材料費等）の回収額。通常0円。発生月のみ入力。 | D36: ★発生月のみ入力 | E36: S列に直接入力
A38: ■ よくあるトラブル・Q&A
A39: Q: 月次集計が 0になる | B39: → 出退勤入力のB列（社員ID）と従業員マスタA列が完全一致しているか確認。スペース・全角/半角・大文字/小文字が1字でも違うと集計されない。 確認方法：出退勤入力B列のセルをクリックして、マスタA列の同じIDを目視で比較する。
A40: Q: 時給社員の 給与が0になる | B40: → ①従業員マスタG列（時間単価）が空欄でないか確認（菊川・濱津等） ②出退勤入力のH・I列（出退勤時刻）が入力されているか確認 ③月次集計T列（実働時間合計）が0でないか確認（0なら①②を見直す）
A41: Q: 従業員を 追加したい | B41: → ①従業員マスタに新行を追加（EMP018、EMP019...と連番）し、全項目を入力 ②月次集計に同じIDで行を追加し、数式を1行上からコピー（合計行より上に追加） ③給与計算も同様に行を追加して数式をコピー（合計行より上に追加）
A42: Q: 従業員が 退職した | B42: → ①従業員マスタのE列（在籍状況）を「退職」に変更する ②月次集計・給与計算の行はそのまま残す（過去データの参照のため） ③翌月から出退勤入力に該当者のデータを入力しなければ自動的に0円になる
A43: Q: 保険料額が 変わった | B43: → 従業員マスタの該当列（H：健保、I：厚生、K：所得税）の金額を更新する。変更月から新金額が自動適用される。変更前の金額はO列（備考）に記録しておくと良い。
A44: Q: 住民税額が変わった （毎年6月） | B44: → 毎年5〜6月に市区町村から「特別徴収税額の決定通知書」が届く。通知書の月額を従業員マスタのL列（住民税）に入力し直す。6月の給与から新金額を適用する。
A45: Q: 実習生が会社都合で 欠勤した | B45: → 出退勤入力に「欠勤」区分で記録。給与計算のJ列（手当合計）に休業手当を計算して入力する。 ★休業手当＝過去3ヶ月平均賃金（総支給÷暦日数）×60%以上（労基法第26条） ★未払は法律違反になるため必ず支払うこと。
...

Sheet 📊計算ロジック説明
A1: 有限会社 東輝 給与計算ロジック説明書（担当者向け詳細資料）
A2: ★ このシートは説明専用です。直接編集しないでください。給与計算の仕組みを理解するための参考資料です。
A4: ■ 給与計算シート 全列の説明（A〜T列）
A5: 列 | B5: 列の名前 | C5: 計算式・取得元 | D5: 詳細説明・注意事項 | E5: 入力者・タイミング
A6: A | B6: 社員ID | C6: 手動入力（変更不可） | D6: EMP001形式。従業員マスタA列と完全一致が必要。変更すると全参照が壊れる。 | E6: 入退社時のみ
A7: B | B7: 氏名 | C7: VLOOKUP(社員ID,マスタ,2) | D7: マスタB列から自動取得。 | E7: 自動
A8: C | B8: 雇用区分 | C8: VLOOKUP(社員ID,マスタ,4) | D8: 月給・日給・時給のいずれか。H列の計算方式がこの値で切り替わる。 | E8: 自動
A9: D | B9: 基本給/日給単価 | C9: VLOOKUP(マスタF列) | D9: 月給→月額固定、日給→1日単価。時給制はG列（時間単価）が実際の計算に使われる。 | E9: 自動
A10: E | B10: 出勤日数 | C10: VLOOKUP(→月次集計C) | D10: 月次集計から自動取得。出退勤入力「○」区分の日数。 | E10: 自動
A11: F | B11: 残業時間 | C11: VLOOKUP(→月次集計H) | D11: 月次集計から自動取得。出退勤入力J列の月合計。 | E11: 自動
A12: G | B12: 有給日数 | C12: VLOOKUP(→月次集計E) | D12: 月次集計から自動取得。「有給」区分のカウント。 | E12: 自動
A13: H | B13: 基本給支給額 | C13: 月給→D列固定 日給→D×E 時給→マスタG(時給)×月次集計T(実働時間) | D13: C列の雇用区分に応じて自動切替。時給制のみ月次集計T列（実働時間合計）を使用する。 | E13: 自動
A14: I | B14: 残業手当 | C14: マスタG(時給)×F(残業時間)×1.25 | D14: 法定残業割増25%込み。時間単価はマスタG列から自動取得。 | E14: 自動
A15: J | B15: 手当合計 ★手動入力 | C15: ★毎月手動入力 | D15: 現場手当・役職手当・通勤手当・実習生割増手当・欠勤控除（マイナス可）など。自動計算されない手当の合計をここに入力する。 | E15: ★毎月必ず確認・入力
A16: K | B16: 総支給額 | C16: H+I+J | D16: 基本給＋残業手当＋手当の合計（税・保険控除前の総額）。 | E16: 自動
... A25: T | B25: 手取金額（最終） | C25: P-Q-R-S | D25: 実際の支払金額。住民税・友愛会費・立替金を全て差し引いた後の最終額。 | E25: 自動
A28: ■ 出退勤入力 出勤区分コードの意味と給与計算への影響
A29: 区分コード | B29: 意味 | C29: 日数カウント先 | D29: 給与計算での扱い | E29: 使い方の例
A30: ○ | B30: 通常出勤 | C30: C列（出勤日数） | D30: 日給制：C列×日給単価が基本給。時給制：実働時間から給与計算。月給制：固定給のため影響なし。 | E30: 普通に出勤した日は全て「○」
A31: △ | B31: 半日出勤 | C31: D列（半日出勤） | D31: 日給制：0.5日分として計算。時給制：実働時間から4時間として計算。 | E31: 午前のみ・午後のみ出勤の場合
A32: 出 | B32: 休日出勤 | C32: F列（休日出勤） | D32: 基本給の計算外。法定休日は日給×1.35倍以上の割増手当をJ列に手入力する。 | E32: 土日・祝日に出勤した場合
A33: 有給 | B33: 有給休暇 | C33: E列（有給日数） | D33: 日給制でも1日分の給与が保証される。有給消化記録として年間管理が必要。 | E33: 有給休暇を取得した日
A34: 欠勤 | B34: 欠勤 | C34: G列（欠勤日数） | D34: 月給制・実習生：欠勤控除が必要（J列でマイナス入力）。日給制：出勤していないため給与なし。 | E34: 無断欠勤・届出欠勤の場合

Sheet 従業員マスタ
A1: 有限会社 東輝 従業員マスタ ★黄色行=毎月確認 ★住民税(L列)は毎年6月更新 ★保険料(H・I列)は改定通知後に更新
A2: 社員ID | B2: 氏名 | C2: 氏名カナ | D2: 雇用区分 | E2: 在籍状況 | F2: 基本給 /日給単価 | G2: 時間単価 | H2: 健康保険 | I2: 厚生年金 | J2: 雇用保険率 | K2: 所得税 | L2: 住民税 | M2: 友愛会 | N2: 入社日 | O2: 備考
A3: EMP001 | B3: 中原 健作 | C3: ナカハラ ケンサク | D3: 月給 | E3: 在籍 | F3: 460000 | H3: 27565 | I3: 43005 | J3: 0 | K3: 14920 | L3: 21800 | M3: 3000 | N3: 2010/04/01
A4: EMP002 | B4: 中原 義範 | C4: ナカハラ ヨシノリ | D4: 月給 | E4: 在籍 | F4: 400000 | H4: 20725 | I4: 37515 | J4: 0 | K4: 23290 | L4: 12300 | M4: 3000 | N4: 2008/04/01
A5: EMP003 | B5: 有田 忍 | C5: アリタ シノブ | D5: 日給 | E5: 在籍 | F5: 13000 | G5: 1625 | H5: 17595 | I5: 27450 | J5: 0.006 | K5: 7180 | L5: 13700 | M5: 3000 | N5: 2012/06/01
A6: EMP004 | B6: 中原 裟也茄 | C6: ナカハラ サヤカ | D6: 日給 | E6: 在籍 | F6: 14000 | G6: 1750 | H6: 15165 | I6: 27450 | J6: 0.006 | K6: 7930 | L6: 17000 | M6: 3000 | N6: 2015/04/01
A7: EMP005 | B7: 廣瀬 伸二 | C7: ヒロセ シンジ | D7: 月給 | E7: 在籍 | J7: 0.006
A8: EMP006 | B8: 山田 一光 | C8: ヤマダ カズミツ | D8: 日給 | E8: 在籍 | F8: 11000 | G8: 1375 | H8: 0 | I8: 0 | J8: 0.006 | K8: 0 | L8: 3800 | M8: 3000 | N8: 2018/04/01
A9: EMP007 | B9: 中原 宏 | C9: ナカハラ ヒロシ | D9: 日給 | E9: 在籍 | F9: 12000 | G9: 1500 | H9: 12132 | I9: 21960 | J9: 0.006 | K9: 4050 | L9: 0 | M9: 3000 | N9: 2019/04/01
A10: EMP008 | B10: アルフィアン ソレフル ハディ | C10: アルフィアン | D10: 月給 | E10: 在籍 | F10: 216667 | G10: 1250 | H10: 9604 | I10: 17385 | J10: 0.006 | K10: 3550 | L10: 1200 | O10: 実習生
A11: EMP009 | B11: ムハンマド ヨザテュル イスラム | C11: ヨザ | D11: 月給 | E11: 在籍 | F11: 216667 | G11: 1250 | H11: 9604 | I11: 17385 | J11: 0.006 | K11: 1940 | L11: 1200 | O11: 実習生
A12: EMP010 | B12: リズキ ノビアント | C12: リズキ | D12: 月給 | E12: 在籍 | F12: 183214 | G12: 1057 | H12: 8593 | I12: 15555 | J12: 0.006 | K12: 910 | L12: 0 | O12: 実習生
A13: EMP011 | B13: ディマス サトリオ ブアナ | C13: ディマス | D13: 月給 | E13: 在籍 | F13: 183214 | G13: 1057 | H13: 8593 | I13: 15555 | J13: 0.006 | K13: 810 | L13: 0 | O13: 実習生
A14: EMP012 | B14: 山田 ユカリ | C14: ヤマダ ユカリ | D14: 時給 | E14: 在籍 | G14: 1429 | J14: 0.006
A15: EMP013 | B15: 菊川 裕美 | C15: キクカワ ユミ | D15: 時給 | E15: 在籍 | G15: 1100 | J15: 0.006
A16: EMP014 | B16: 中島 孝信 | C16: ナカシマ タカノブ | D16: 月給 | E16: 在籍 | F16: 300000 | H16: 0 | I16: 0 | J16: 0.006 | K16: 7820 | L16: 0 | O16: 年1回一括支払
A17: EMP015 | B17: 中原 廣子 | C17: ナカハラ ヒロコ | D17: 月給 | E17: 在籍 | F17: 60000 | H17: 0 | I17: 0 | J17: 0 | K17: 0 | L17: 0
A18: EMP016 | B18: 畑野 浩次 | C18: ハタノ コウジ | D18: 月給 | E18: 在籍 | F18: 200000 | J18: 0.006
A19: EMP017 | B19: 濱津 紀子 | C19: ハマツ ノリコ | D19: 時給 | E19: 在籍 | G19: 1057 | J19: 0.006

Sheet 現場マスタ
A1: 有限会社 東輝 現場マスタ
A2: コード | B2: 現場名 | C2: 発注者 | D2: 工事種別 | E2: 備考
A3: A | B3: 会社 | C3: 東輝 | D3: その他
A4: B | B4: 健老町道路排水施設工事 | C4: 大牟田市 | D4: 土木
A5: C | B5: 四山海岸高潮対策工事 | C5: 県土木 | D5: 土木
A6: D | B6: その他 | C6: 東輝 | D6: その他
A7: E | B7: 石綿（アスベスト）講習会 | C7: 外部 | D7: その他
A8: F | B8: 吉野汚水（R7-2工区） | C8: 大牟田市 | D8: 下水
A9: G | B9: （予備）
A10: H | B10: （予備）
A11: I | B11: （予備）
A12: J | B12: （予備）

Sheet 出退勤入力
A1: 出退勤入力 ※1行1レコード形式で入力してください
A2: 日付 | B2: 社員ID | C2: 氏名 （自動） | D2: 区分 （自動） | E2: 出勤区分 | F2: 現場 コード | G2: 現場名 （自動） | H2: 出勤時刻 | I2: 退勤時刻 | J2: 残業時間 (h) | K2: 遅刻早退 (h) | L2: 備考 | M2: 実働時間(h) 【自動計算】 6h以上→休憩1h控除
A3: 46126 | B3: EMP012 | C3: 山田ゆかり | E3: ○ | F3: A | G3: 会社 | H3: 0.37222222 | I3: 0.7125 | J3: 0.15 | K3: 0 | M3: =IFERROR(IF(AND(H3<>"",I3<>""),ROUND(MAX(0,(I3-H3)*24-IF((I3-H3)*24>=6,1,0)),2),IF(E3="△",4,0)),0)
A4: 46126 | B4: EMP016 | C4: 畑野浩次 | E4: ○ | F4: A | G4: 会社 | H4: 0.37222222 | I4: 0.7125 | J4: 0.15 | K4: 0 | M4: =IFERROR(IF(AND(H4<>"",I4<>""),ROUND(MAX(0,(I4-H4)*24-IF((I4-H4)*24>=6,1,0)),2),IF(E4="△",4,0)),0)
A5: 46126 | B5: EMP013 | C5: 菊川裕美 | E5: ○ | F5: A | G5: 会社 | H5: 0.36666667 | I5: 0.62708333 | J5: 0 | K5: 0 | M5: =IFERROR(IF(AND(H5<>"",I5<>""),ROUND(MAX(0,(I5-H5)*24-IF((I5-H5)*24>=6,1,0)),2),IF(E5="△",4,0)),0)
A6: 46126 | B6: EMP017 | C6: 濱津紀子 | E6: ○ | F6: A | G6: 会社 | H6: 0.37152778 | I6: 0.62847222 | J6: 0 | K6: 0 | M6: =IFERROR(IF(AND(H6<>"",I6<>""),ROUND(MAX(0,(I6-H6)*24-IF((I6-H6)*24>=6,1,0)),2),IF(E6="△",4,0)),0)
A7: 46126 | B7: EMP002 | C7: 中原義範 | E7: ○ | F7: A | G7: 会社 | H7: 0.34097222 | I7: 0.61666667 | J7: 0 | K7: 0 | M7: =IFERROR(IF(AND(H7<>"",I7<>""),ROUND(MAX(0,(I7-H7)*24-IF((I7-H7)*24>=6,1,0)),2),IF(E7="△",4,0)),0)
A8: 46126 | B8: EMP004 | C8: 中原裟也茄 | E8: ○ | F8: A | G8: 会社 | H8: 0.3375 | I8: 0.73055556 | J8: 1.42 | K8: 0 | M8: =IFERROR(IF(AND(H8<>"",I8<>""),ROUND(MAX(0,(I8-H8)*24-IF((I8-H8)*24>=6,1,0)),2),IF(E8="△",4,0)),0)
A9: 46126 | B9: EMP007 | C9: 中原宏 | E9: ○ | F9: B | G9: 健老町道路排水施設工事 | H9: 0.33333333 | I9: 0.60416667 | J9: 0 | K9: 0 | L9: 半日 | M9: =IFERROR(IF(AND(H9<>"",I9<>""),ROUND(MAX(0,(I9-H9)*24-IF((I9-H9)*24>=6,1,0)),2),IF(E9="△",4,0)),0)
A10: 46126 | B10: EMP003 | C10: 有田忍 | E10: ○ | F10: B | G10: 健老町道路排水施設工事 | H10: 0.31875 | I10: 0.60416667 | J10: 0 | K10: 0 | M10: =IFERROR(IF(AND(H10<>"",I10<>""),ROUND(MAX(0,(I10-H10)*24-IF((I10-H10)*24>=6,1,0)),2),IF(E10="△",4,0)),0)
A11: 46126 | B11: EMP009 | C11: ヨザ | E11: ○ | F11: B | G11: 健老町道路排水施設工事 | H11: 0.33333333 | I11: 0.60416667 | J11: 0 | K11: 0 | M11: =IFERROR(IF(AND(H11<>"",I11<>""),ROUND(MAX(0,(I11-H11)*24-IF((I11-H11)*24>=6,1,0)),2),IF(E11="△",4,0)),0)
A12: 46126 | B12: EMP008 | C12: アルフィ | E12: ○ | F12: A | G12: 会社 | H12: 0.33333333 | I12: 0.60416667 | J12: 0 | K12: 0 | M12: =IFERROR(IF(AND(H12<>"",I12<>""),ROUND(MAX(0,(I12-H12)*24-IF((I12-H12)*24>=6,1,0)),2),IF(E12="△",4,0)),0)
A13: 46126 | B13: EMP010 | C13: リズキ | E13: ○ | F13: B | G13: 健老町道路排水施設工事 | H13: 0.33333333 | I13: 0.60416667 | J13: 0 | K13: 0 | M13: =IFERROR(IF(AND(H13<>"",I13<>""),ROUND(MAX(0,(I13-H13)*24-IF((I13-H13)*24>=6,1,0)),2),IF(E13="△",4,0)),0)
A14: 46126 | B14: EMP011 | C14: ディマス | E14: ○ | F14: B | G14: 健老町道路排水施設工事 | H14: 0.33333333 | I14: 0.60416667 | J14: 0 | K14: 0 | M14: =IFERROR(IF(AND(H14<>"",I14<>""),ROUND(MAX(0,(I14-H14)*24-IF((I14-H14)*24>=6,1,0)),2),IF(E14="△",4,0)),0)
A15: 46127 | B15: EMP012 | C15: 山田ゆかり | E15: ○ | F15: A | G15: 会社 | H15: 0.37222222 | I15: 0.71458333 | J15: 0 | K15: 0 | M15: =IFERROR(IF(AND(H15<>"",I15<>""),ROUND(MAX(0,(I15-H15)*24-IF((I15-H15)*24>=6,1,0)),2),IF(E15="△",4,0)),0)
A16: 46127 | B16: EMP016 | C16: 畑野浩次 | E16: ○ | F16: A | G16: 会社 | H16: 0.35902778 | I16: 0.71111111 | J16: 0 | K16: 0 | M16: =IFERROR(IF(AND(H16<>"",I16<>""),ROUND(MAX(0,(I16-H16)*24-IF((I16-H16)*24>=6,1,0)),2),IF(E16="△",4,0)),0)
A17: 46127 | B17: EMP013 | C17: 菊川裕美 | E17: ○ | F17: A | G17: 会社 | H17: 0.36736111 | I17: 0.62916667 | J17: 0 | K17: 0 | M17: =IFERROR(IF(AND(H17<>"",I17<>""),ROUND(MAX(0,(I17-H17)*24-IF((I17-H17)*24>=6,1,0)),2),IF(E17="△",4,0)),0)
A18: 46127 | B18: EMP017 | C18: 濱津紀子 | E18: ○ | F18: A | G18: 会社 | H18: 0.37361111 | I18: 0.63611111 | J18: 0 | K18: 0 | M18: =IFERROR(IF(AND(H18<>"",I18<>""),ROUND(MAX(0,(I18-H18)*24-IF((I18-H18)*24>=6,1,0)),2),IF(E18="△",4,0)),0)
A19: 46127 | C19: 宮川正利 | E19: ○ | F19: B | G19: 健老町道路排水施設工事 | H19: 0.33333333 | I19: 0.71805556 | J19: 0.23 | K19: 0 | M19: =IFERROR(IF(AND(H19<>"",I19<>""),ROUND(MAX(0,(I19-H19)*24-IF((I19-H19)*24>=6,1,0)),2),IF(E19="△",4,0)),0)
A20: 46127 | B20: EMP002 | C20: 中原義範 | E20: ○ | F20: A | G20: 会社 | H20: 0.33194444 | I20: 0.72916667 | J20: 0.53 | K20: 0 | M20: =IFERROR(IF(AND(H20<>"",I20<>""),ROUND(MAX(0,(I20-H20)*24-IF((I20-H20)*24>=6,1,0)),2),IF(E20="△",4,0)),0)
A21: 46127 | B21: EMP004 | C21: 中原裟也茄 | E21: ○ | F21: A | G21: 会社 | H21: 0.33263889 | I21: 0.74652778 | J21: 0.93 | K21: 0 | M21: =IFERROR(IF(AND(H21<>"",I21<>""),ROUND(MAX(0,(I21-H21)*24-IF((I21-H21)*24>=6,1,0)),2),IF(E21="△",4,0)),0)
A22: 46127 | B22: EMP007 | C22: 中原宏 | E22: ○ | F22: B | G22: 健老町道路排水施設工事 | H22: 0.33263889 | I22: 0.71666667 | J22: 0.22 | K22: 0 | M22: =IFERROR(IF(AND(H22<>"",I22<>""),ROUND(MAX(0,(I22-H22)*24-IF((I22-H22)*24>=6,1,0)),2),IF(E22="△",4,0)),0)
A23: 46127 | B23: EMP003 | C23: 有田忍 | E23: ○ | F23: B | G23: 健老町道路排水施設工事 | H23: 0.33055556 | I23: 0.80555556 | J23: 2.38 | K23: 0 | M23: =IFERROR(IF(AND(H23<>"",I23<>""),ROUND(MAX(0,(I23-H23)*24-IF((I23-H23)*24>=6,1,0)),2),IF(E23="△",4,0)),0)
A24: 46127 | B24: EMP009 | C24: ヨザ | E24: ○ | F24: B | G24: 健老町道路排水施設工事 | H24: 0.30694444 | I24: 0.71527778 | J24: 0.78 | K24: 0 | M24: =IFERROR(IF(AND(H24<>"",I24<>""),ROUND(MAX(0,(I24-H24)*24-IF((I24-H24)*24>=6,1,0)),2),IF(E24="△",4,0)),0)
A25: 46127 | B25: EMP008 | C25: アルフィ | E25: ○ | F25: B | G25: 健老町道路排水施設工事 | H25: 0.30694444 | I25: 0.71944444 | J25: 0.88 | K25: 0 | M25: =IFERROR(IF(AND(H25<>"",I25<>""),ROUND(MAX(0,(I25-H25)*24-IF((I25-H25)*24>=6,1,0)),2),IF(E25="△",4,0)),0)
A26: 46127 | B26: EMP010 | C26: リズキ | E26: ○ | F26: B | G26: 健老町道路排水施設工事 | H26: 0.3125 | I26: 0.71597222 | J26: 0.68 | K26: 0 | M26: =IFERROR(IF(AND(H26<>"",I26<>""),ROUND(MAX(0,(I26-H26)*24-IF((I26-H26)*24>=6,1,0)),2),IF(E26="△",4,0)),0)
A27: 46127 | B27: EMP011 | C27: ディマス | E27: ○ | F27: B | G27: 健老町道路排水施設工事 | H27: 0.31597222 | I27: 0.71597222 | J27: 0.6 | K27: 0 | M27: =IFERROR(IF(AND(H27<>"",I27<>""),ROUND(MAX(0,(I27-H27)*24-IF((I27-H27)*24>=6,1,0)),2),IF(E27="△",4,0)),0)
A28: 46128 | B28: EMP012 | C28: 山田ゆかり | E28: ○ | F28: A | G28: 会社 | H28: 0.36319444 | I28: 0.71111111 | J28: 0 | K28: 0 | M28: =IFERROR(IF(AND(H28<>"",I28<>""),ROUND(MAX(0,(I28-H28)*24-IF((I28-H28)*24>=6,1,0)),2),IF(E28="△",4,0)),0)
A29: 46128 | B29: EMP016 | C29: 畑野浩次 | E29: ○ | F29: A | G29: 会社 | H29: 0.36041667 | I29: 0.71875 | J29: 0 | K29: 0 | M29: =IFERROR(IF(AND(H29<>"",I29<>""),ROUND(MAX(0,(I29-H29)*24-IF((I29-H29)*24>=6,1,0)),2),IF(E29="△",4,0)),0)
A30: 46128 | B30: EMP013 | C30: 菊川裕美 | E30: ○ | F30: A | G30: 会社 | H30: 0.36458333 | I30: 0.62847222 | J30: 0 | K30: 0 | M30: =IFERROR(IF(AND(H30<>"",I30<>""),ROUND(MAX(0,(I30-H30)*24-IF((I30-H30)*24>=6,1,0)),2),IF(E30="△",4,0)),0)
A31: 46128 | B31: EMP017 | C31: 濱津紀子 | E31: ○ | F31: A | G31: 会社 | H31: 0.37152778 | I31: 0.62708333 | J31: 0 | K31: 0 | M31: =IFERROR(IF(AND(H31<>"",I31<>""),ROUND(MAX(0,(I31-H31)*24-IF((I31-H31)*24>=6,1,0)),2),IF(E31="△",4,0)),0)
A32: 46128 | C32: 河津 信貴 | E32: ○ | F32: B | G32: 健老町道路排水施設工事 | H32: 0.32638889 | I32: 0.71944444 | J32: 0.42 | K32: 0 | M32: =IFERROR(IF(AND(H32<>"",I32<>""),ROUND(MAX(0,(I32-H32)*24-IF((I32-H32)*24>=6,1,0)),2),IF(E32="△",4,0)),0)
A33: 46128 | C33: 宮川正利 | E33: ○ | F33: B | G33: 健老町道路排水施設工事 | H33: 0.31736111 | I33: 0.71944444 | J33: 0.65 | K33: 0 | M33: =IFERROR(IF(AND(H33<>"",I33<>""),ROUND(MAX(0,(I33-H33)*24-IF((I33-H33)*24>=6,1,0)),2),IF(E33="△",4,0)),0)
A34: 46128 | B34: EMP002 | C34: 中原義範 | E34: ○ | F34: A | G34: 会社 | H34: 0.37013889 | I34: 0.73680556 | J34: 0 | K34: 0 | M34: =IFERROR(IF(AND(H34<>"",I34<>""),ROUND(MAX(0,(I34-H34)*24-IF((I34-H34)*24>=6,1,0)),2),IF(E34="△",4,0)),0)
A35: 46128 | B35: EMP004 | C35: 中原裟也茄 | E35: ○ | F35: A | G35: 会社 | H35: 0.33333333 | I35: 0.79861111 | J35: 2.15 | K35: 0 | M35: =IFERROR(IF(AND(H35<>"",I35<>""),ROUND(MAX(0,(I35-H35)*24-IF((I35-H35)*24>=6,1,0)),2),IF(E35="△",4,0)),0)
A36: 46128 | B36: EMP007 | C36: 中原宏 | E36: ○ | F36: B | G36: 健老町道路排水施設工事 | H36: 0.33333333 | I36: 0.71458333 | J36: 0.15 | K36: 0 | M36: =IFERROR(IF(AND(H36<>"",I36<>""),ROUND(MAX(0,(I36-H36)*24-IF((I36-H36)*24>=6,1,0)),2),IF(E36="△",4,0)),0)
A37: 46128 | B37: EMP003 | C37: 有田忍 | E37: ○ | F37: B | G37: 健老町道路排水施設工事 | H37: 0.32361111 | I37: 0.81736111 | J37: 2.83 | K37: 0 | M37: =IFERROR(IF(AND(H37<>"",I37<>""),ROUND(MAX(0,(I37-H37)*24-IF((I37-H37)*24>=6,1,0)),2),IF(E37="△",4,0)),0)
A38: 46128 | B38: EMP009 | C38: ヨザ | E38: ○ | F38: B | G38: 健老町道路排水施設工事 | H38: 0.30347222 | I38: 0.71736111 | J38: 0.93 | K38: 0 | M38: =IFERROR(IF(AND(H38<>"",I38<>""),ROUND(MAX(0,(I38-H38)*24-IF((I38-H38)*24>=6,1,0)),2),IF(E38="△",4,0)),0)
A39: 46128 | B39: EMP008 | C39: アルフィ | E39: ○ | F39: B | G39: 健老町道路排水施設工事 | H39: 0.30277778 | I39: 0.71666667 | J39: 0.93 | K39: 0 | M39: =IFERROR(IF(AND(H39<>"",I39<>""),ROUND(MAX(0,(I39-H39)*24-IF((I39-H39)*24>=6,1,0)),2),IF(E39="△",4,0)),0)
A40: 46128 | B40: EMP010 | C40: リズキ | E40: ○ | F40: B | G40: 健老町道路排水施設工事 | H40: 0.30833333 | I40: 0.71805556 | J40: 0.83 | K40: 0 | M40: =IFERROR(IF(AND(H40<>"",I40<>""),ROUND(MAX(0,(I40-H40)*24-IF((I40-H40)*24>=6,1,0)),2),IF(E40="△",4,0)),0)
...

Sheet 月次集計
A1: 月次勤怠集計表
A2: 集計年月: | C2: =DATE(E2,F2,1) | D2: 年: | E2: 2026 | F2: 4 | G2: 月 | H2: ※ E2に年、F2に月を入力してください 黄色セル=入力箇所 | T2: ↓時給計算用（自動）
A3: 社員ID | B3: 氏名 | C3: 出勤 日数 | D3: 半日 出勤 | E3: 有給 休暇 | F3: 休日 出勤 | G3: 欠勤 日数 | H3: 残業 時間(h) | I3: 遅刻早退 時間(h) | J3: 現場A | K3: 現場B | L3: 現場C | M3: 現場D | N3: 現場E | O3: 現場F | P3: 基本給 | Q3: 残業手当 | R3: 現場手当 等 | S3: 総支給 | T3: 実働時間 合計(h) 【時給計算用】
A4: EMP001 | B4: =IFERROR(VLOOKUP(A4,従業員マスタ!$A:$B,2,0),"") | C4: =COUNTIFS(出退勤入力!$B:$B,A4,出退勤入力!$A:$A,">="&DATE(月次集計!$E$2,月次集計!$F$2,1),出退勤入力!$A:$A,"<="&DATE(月次集計!$E$2,月次集計!$F$2+1,0),出退勤入力!$E:$E,"○") | D4: =COUNTIFS(出退勤入力!$B:$B,A4,出退勤入力!$A:$A,">="&DATE(月次集計!$E$2,月次集計!$F$2,1),出退勤入力!$A:$A,"<="&DATE(月次集計!$E$2,月次集計!$F$2+1,0),出退勤入力!$E:$E,"△") | E4: =COUNTIFS(出退勤入力!$B:$B,A4,出退勤入力!$A:$A,">="&DATE(月次集計!$E$2,月次集計!$F$2,1),出退勤入力!$A:$A,"<="&DATE(月次集計!$E$2,月次集計!$F$2+1,0),出退勤入力!$E:$E,"有給") | F4: =COUNTIFS(出退勤入力!$B:$B,A4,出退勤入力!$A:$A,">="&DATE(月次集計!$E$2,月次集計!$F$2,1),出退勤入力!$A:$A,"<="&DATE(月次集計!$E$2,月次集計!$F$2+1,0),出退勤入力!$E:$E,"出") | G4: =COUNTIFS(出退勤入力!$B:$B,A4,出退勤入力!$A:$A,">="&DATE(月次集計!$E$2,月次集計!$F$2,1),出退勤入力!$A:$A,"<="&DATE(月次集計!$E$2,月次集計!$F$2+1,0),出退勤入力!$E:$E,"欠勤") | H4: =IFERROR(SUMIFS(出退勤入力!$J:$J,出退勤入力!$B:$B,A4,出退勤入力!$A:$A,">="&DATE(月次集計!$E$2,月次集計!$F$2,1),出退勤入力!$A:$A,"<="&DATE(月次集計!$E$2,月次集計!$F$2+1,0)),0) | I4: =IFERROR(SUMIFS(出退勤入力!$K:$K,出退勤入力!$B:$B,A4,出退勤入力!$A:$A,">="&DATE(月次集計!$E$2,月次集計!$F$2,1),出退勤入力!$A:$A,"<="&DATE(月次集計!$E$2,月次集計!$F$2+1,0)),0) | J4: =COUNTIFS(出退勤入力!$B:$B,A4,出退勤入力!$A:$A,">="&DATE(月次集計!$E$2,月次集計!$F$2,1),出退勤入力!$A:$A,"<="&DATE(月次集計!$E$2,月次集計!$F$2+1,0),出退勤入力!$F:$F,"A") | K4: =COUNTIFS(出退勤入力!$B:$B,A4,出退勤入力!$A:$A,">="&DATE(月次集計!$E$2,月次集計!$F$2,1),出退勤入力!$A:$A,"<="&DATE(月次集計!$E$2,月次集計!$F$2+1,0),出退勤入力!$F:$F,"B") | L4: =COUNTIFS(出退勤入力!$B:$B,A4,出退勤入力!$A:$A,">="&DATE(月次集計!$E$2,月次集計!$F$2,1),出退勤入力!$A:$A,"<="&DATE(月次集計!$E$2,月次集計!$F$2+1,0),出退勤入力!$F:$F,"C") | M4: =COUNTIFS(出退勤入力!$B:$B,A4,出退勤入力!$A:$A,">="&DATE(月次集計!$E$2,月次集計!$F$2,1),出退勤入力!$A:$A,"<="&DATE(月次集計!$E$2,月次集計!$F$2+1,0),出退勤入力!$F:$F,"D") | N4: =COUNTIFS(出退勤入力!$B:$B,A4,出退勤入力!$A:$A,">="&DATE(月次集計!$E$2,月次集計!$F$2,1),出退勤入力!$A:$A,"<="&DATE(月次集計!$E$2,月次集計!$F$2+1,0),出退勤入力!$F:$F,"E") | O4: =COUNTIFS(出退勤入力!$B:$B,A4,出退勤入力!$A:$A,">="&DATE(月次集計!$E$2,月次集計!$F$2,1),出退勤入力!$A:$A,"<="&DATE(月次集計!$E$2,月次集計!$F$2+1,0),出退勤入力!$F:$F,"F") | P4: =IFERROR(VLOOKUP(A4,従業員マスタ!$A:$F,6,0),0) | Q4: =IFERROR(VLOOKUP(A4,従業員マスタ!$A:$G,7,0)*H4*1.25,0) | R4: 0 | S4: =IFERROR(P4+Q4+R4,0) | T4: =IFERROR(SUMIFS(出退勤入力!$M:$M,出退勤入力!$B:$B,A4,出退勤入力!$A:$A,">="&DATE($E$2,$F$2,1),出退勤入力!$A:$A,"<="&DATE($E$2,$F$2+1,0)),0)
A5: EMP002 | B5: =IFERROR(VLOOKUP(A5,従業員マスタ!$A:$B,2,0),"") | C5: =COUNTIFS(出退勤入力!$B:$B,A5,出退勤入力!$A:$A,">="&DATE(月次集計!$E$2,月次集計!$F$2,1),出退勤入力!$A:$A,"<="&DATE(月次集計!$E$2,月次集計!$F$2+1,0),出退勤入力!$E:$E,"○") | D5: =COUNTIFS(出退勤入力!$B:$B,A5,出退勤入力!$A:$A,">="&DATE(月次集計!$E$2,月次集計!$F$2,1),出退勤入力!$A:$A,"<="&DATE(月次集計!$E$2,月次集計!$F$2+1,0),出退勤入力!$E:$E,"△") | E5: =COUNTIFS(出退勤入力!$B:$B,A5,出退勤入力!$A:$A,">="&DATE(月次集計!$E$2,月次集計!$F$2,1),出退勤入力!$A:$A,"<="&DATE(月次集計!$E$2,月次集計!$F$2+1,0),出退勤入力!$E:$E,"有給") | F5: =COUNTIFS(出退勤入力!$B:$B,A5,出退勤入力!$A:$A,">="&DATE(月次集計!$E$2,月次集計!$F$2,1),出退勤入力!$A:$A,"<="&DATE(月次集計!$E$2,月次集計!$F$2+1,0),出退勤入力!$E:$E,"出") | G5: =COUNTIFS(出退勤入力!$B:$B,A5,出退勤入力!$A:$A,">="&DATE(月次集計!$E$2,月次集計!$F$2,1),出退勤入力!$A:$A,"<="&DATE(月次集計!$E$2,月次集計!$F$2+1,0),出退勤入力!$E:$E,"欠勤") | H5: =IFERROR(SUMIFS(出退勤入力!$J:$J,出退勤入力!$B:$B,A5,出退勤入力!$A:$A,">="&DATE(月次集計!$E$2,月次集計!$F$2,1),出退勤入力!$A:$A,"<="&DATE(月次集計!$E$2,月次集計!$F$2+1,0)),0) | I5: =IFERROR(SUMIFS(出退勤入力!$K:$K,出退勤入力!$B:$B,A5,出退勤入力!$A:$A,">="&DATE(月次集計!$E$2,月次集計!$F$2,1),出退勤入力!$A:$A,"<="&DATE(月次集計!$E$2,月次集計!$F$2+1,0)),0) | J5: =COUNTIFS(出退勤入力!$B:$B,A5,出退勤入力!$A:$A,">="&DATE(月次集計!$E$2,月次集計!$F$2,1),出退勤入力!$A:$A,"<="&DATE(月次集計!$E$2,月次集計!$F$2+1,0),出退勤入力!$F:$F,"A") | K5: =COUNTIFS(出退勤入力!$B:$B,A5,出退勤入力!$A:$A,">="&DATE(月次集計!$E$2,月次集計!$F$2,1),出退勤入力!$A:$A,"<="&DATE(月次集計!$E$2,月次集計!$F$2+1,0),出退勤入力!$F:$F,"B") | L5: =COUNTIFS(出退勤入力!$B:$B,A5,出退勤入力!$A:$A,">="&DATE(月次集計!$E$2,月次集計!$F$2,1),出退勤入力!$A:$A,"<="&DATE(月次集計!$E$2,月次集計!$F$2+1,0),出退勤入力!$F:$F,"C") | M5: =COUNTIFS(出退勤入力!$B:$B,A5,出退勤入力!$A:$A,">="&DATE(月次集計!$E$2,月次集計!$F$2,1),出退勤入力!$A:$A,"<="&DATE(月次集計!$E$2,月次集計!$F$2+1,0),出退勤入力!$F:$F,"D") | N5: =COUNTIFS(出退勤入力!$B:$B,A5,出退勤入力!$A:$A,">="&DATE(月次集計!$E$2,月次集計!$F$2,1),出退勤入力!$A:$A,"<="&DATE(月次集計!$E$2,月次集計!$F$2+1,0),出退勤入力!$F:$F,"E") | O5: =COUNTIFS(出退勤入力!$B:$B,A5,出退勤入力!$A:$A,">="&DATE(月次集計!$E$2,月次集計!$F$2,1),出退勤入力!$A:$A,"<="&DATE(月次集計!$E$2,月次集計!$F$2+1,0),出退勤入力!$F:$F,"F") | P5: =IFERROR(VLOOKUP(A5,従業員マスタ!$A:$F,6,0),0) | Q5: =IFERROR(VLOOKUP(A5,従業員マスタ!$A:$G,7,0)*H5*1.25,0) | R5: 0 | S5: =IFERROR(P5+Q5+R5,0) | T5: =IFERROR(SUMIFS(出退勤入力!$M:$M,出退勤入力!$B:$B,A5,出退勤入力!$A:$A,">="&DATE($E$2,$F$2,1),出退勤入力!$A:$A,"<="&DATE($E$2,$F$2+1,0)),0)
A6: EMP003 | B6: =IFERROR(VLOOKUP(A6,従業員マスタ!$A:$B,2,0),"") | C6: =COUNTIFS(出退勤入力!$B:$B,A6,出退勤入力!$A:$A,">="&DATE(月次集計!$E$2,月次集計!$F$2,1),出退勤入力!$A:$A,"<="&DATE(月次集計!$E$2,月次集計!$F$2+1,0),出退勤入力!$E:$E,"○") | D6: =COUNTIFS(出退勤入力!$B:$B,A6,出退勤入力!$A:$A,">="&DATE(月次集計!$E$2,月次集計!$F$2,1),出退勤入力!$A:$A,"<="&DATE(月次集計!$E$2,月次集計!$F$2+1,0),出退勤入力!$E:$E,"△") | E6: =COUNTIFS(出退勤入力!$B:$B,A6,出退勤入力!$A:$A,">="&DATE(月次集計!$E$2,月次集計!$F$2,1),出退勤入力!$A:$A,"<="&DATE(月次集計!$E$2,月次集計!$F$2+1,0),出退勤入力!$E:$E,"有給") | F6: =COUNTIFS(出退勤入力!$B:$B,A6,出退勤入力!$A:$A,">="&DATE(月次集計!$E$2,月次集計!$F$2,1),出退勤入力!$A:$A,"<="&DATE(月次集計!$E$2,月次集計!$F$2+1,0),出退勤入力!$E:$E,"出") | G6: =COUNTIFS(出退勤入力!$B:$B,A6,出退勤入力!$A:$A,">="&DATE(月次集計!$E$2,月次集計!$F$2,1),出退勤入力!$A:$A,"<="&DATE(月次集計!$E$2,月次集計!$F$2+1,0),出退勤入力!$E:$E,"欠勤") | H6: =IFERROR(SUMIFS(出退勤入力!$J:$J,出退勤入力!$B:$B,A6,出退勤入力!$A:$A,">="&DATE(月次集計!$E$2,月次集計!$F$2,1),出退勤入力!$A:$A,"<="&DATE(月次集計!$E$2,月次集計!$F$2+1,0)),0) | I6: =IFERROR(SUMIFS(出退勤入力!$K:$K,出退勤入力!$B:$B,A6,出退勤入力!$A:$A,">="&DATE(月次集計!$E$2,月次集計!$F$2,1),出退勤入力!$A:$A,"<="&DATE(月次集計!$E$2,月次集計!$F$2+1,0)),0) | J6: =COUNTIFS(出退勤入力!$B:$B,A6,出退勤入力!$A:$A,">="&DATE(月次集計!$E$2,月次集計!$F$2,1),出退勤入力!$A:$A,"<="&DATE(月次集計!$E$2,月次集計!$F$2+1,0),出退勤入力!$F:$F,"A") | K6: =COUNTIFS(出退勤入力!$B:$B,A6,出退勤入力!$A:$A,">="&DATE(月次集計!$E$2,月次集計!$F$2,1),出退勤入力!$A:$A,"<="&DATE(月次集計!$E$2,月次集計!$F$2+1,0),出退勤入力!$F:$F,"B") | L6: =COUNTIFS(出退勤入力!$B:$B,A6,出退勤入力!$A:$A,">="&DATE(月次集計!$E$2,月次集計!$F$2,1),出退勤入力!$A:$A,"<="&DATE(月次集計!$E$2,月次集計!$F$2+1,0),出退勤入力!$F:$F,"C") | M6: =COUNTIFS(出退勤入力!$B:$B,A6,出退勤入力!$A:$A,">="&DATE(月次集計!$E$2,月次集計!$F$2,1),出退勤入力!$A:$A,"<="&DATE(月次集計!$E$2,月次集計!$F$2+1,0),出退勤入力!$F:$F,"D") | N6: =COUNTIFS(出退勤入力!$B:$B,A6,出退勤入力!$A:$A,">="&DATE(月次集計!$E$2,月次集計!$F$2,1),出退勤入力!$A:$A,"<="&DATE(月次集計!$E$2,月次集計!$F$2+1,0),出退勤入力!$F:$F,"E") | O6: =COUNTIFS(出退勤入力!$B:$B,A6,出退勤入力!$A:$A,">="&DATE(月次集計!$E$2,月次集計!$F$2,1),出退勤入力!$A:$A,"<="&DATE(月次集計!$E$2,月次集計!$F$2+1,0),出退勤入力!$F:$F,"F") | P6: =IFERROR(VLOOKUP(A6,従業員マスタ!$A:$F,6,0),0) | Q6: =IFERROR(VLOOKUP(A6,従業員マスタ!$A:$G,7,0)*H6*1.25,0) | R6: 0 | S6: =IFERROR(P6+Q6+R6,0) | T6: =IFERROR(SUMIFS(出退勤入力!$M:$M,出退勤入力!$B:$B,A6,出退勤入力!$A:$A,">="&DATE($E$2,$F$2,1),出退勤入力!$A:$A,"<="&DATE($E$2,$F$2+1,0)),0)
A7: EMP004 | B7: =IFERROR(VLOOKUP(A7,従業員マスタ!$A:$B,2,0),"") | C7: =COUNTIFS(出退勤入力!$B:$B,A7,出退勤入力!$A:$A,">="&DATE(月次集計!$E$2,月次集計!$F$2,1),出退勤入力!$A:$A,"<="&DATE(月次集計!$E$2,月次集計!$F$2+1,0),出退勤入力!$E:$E,"○") | D7: =COUNTIFS(出退勤入力!$B:$B,A7,出退勤入力!$A:$A,">="&DATE(月次集計!$E$2,月次集計!$F$2,1),出退勤入力!$A:$A,"<="&DATE(月次集計!$E$2,月次集計!$F$2+1,0),出退勤入力!$E:$E,"△") | E7: =COUNTIFS(出退勤入力!$B:$B,A7,出退勤入力!$A:$A,">="&DATE(月次集計!$E$2,月次集計!$F$2,1),出退勤入力!$A:$A,"<="&DATE(月次集計!$E$2,月次集計!$F$2+1,0),出退勤入力!$E:$E,"有給") | F7: =COUNTIFS(出退勤入力!$B:$B,A7,出退勤入力!$A:$A,">="&DATE(月次集計!$E$2,月次集計!$F$2,1),出退勤入力!$A:$A,"<="&DATE(月次集計!$E$2,月次集計!$F$2+1,0),出退勤入力!$E:$E,"出") | G7: =COUNTIFS(出退勤入力!$B:$B,A7,出退勤入力!$A:$A,">="&DATE(月次集計!$E$2,月次集計!$F$2,1),出退勤入力!$A:$A,"<="&DATE(月次集計!$E$2,月次集計!$F$2+1,0),出退勤入力!$E:$E,"欠勤") | H7: =IFERROR(SUMIFS(出退勤入力!$J:$J,出退勤入力!$B:$B,A7,出退勤入力!$A:$A,">="&DATE(月次集計!$E$2,月次集計!$F$2,1),出退勤入力!$A:$A,"<="&DATE(月次集計!$E$2,月次集計!$F$2+1,0)),0) | I7: =IFERROR(SUMIFS(出退勤入力!$K:$K,出退勤入力!$B:$B,A7,出退勤入力!$A:$A,">="&DATE(月次集計!$E$2,月次集計!$F$2,1),出退勤入力!$A:$A,"<="&DATE(月次集計!$E$2,月次集計!$F$2+1,0)),0) | J7: =COUNTIFS(出退勤入力!$B:$B,A7,出退勤入力!$A:$A,">="&DATE(月次集計!$E$2,月次集計!$F$2,1),出退勤入力!$A:$A,"<="&DATE(月次集計!$E$2,月次集計!$F$2+1,0),出退勤入力!$F:$F,"A") | K7: =COUNTIFS(出退勤入力!$B:$B,A7,出退勤入力!$A:$A,">="&DATE(月次集計!$E$2,月次集計!$F$2,1),出退勤入力!$A:$A,"<="&DATE(月次集計!$E$2,月次集計!$F$2+1,0),出退勤入力!$F:$F,"B") | L7: =COUNTIFS(出退勤入力!$B:$B,A7,出退勤入力!$A:$A,">="&DATE(月次集計!$E$2,月次集計!$F$2,1),出退勤入力!$A:$A,"<="&DATE(月次集計!$E$2,月次集計!$F$2+1,0),出退勤入力!$F:$F,"C") | M7: =COUNTIFS(出退勤入力!$B:$B,A7,出退勤入力!$A:$A,">="&DATE(月次集計!$E$2,月次集計!$F$2,1),出退勤入力!$A:$A,"<="&DATE(月次集計!$E$2,月次集計!$F$2+1,0),出退勤入力!$F:$F,"D") | N7: =COUNTIFS(出退勤入力!$B:$B,A7,出退勤入力!$A:$A,">="&DATE(月次集計!$E$2,月次集計!$F$2,1),出退勤入力!$A:$A,"<="&DATE(月次集計!$E$2,月次集計!$F$2+1,0),出退勤入力!$F:$F,"E") | O7: =COUNTIFS(出退勤入力!$B:$B,A7,出退勤入力!$A:$A,">="&DATE(月次集計!$E$2,月次集計!$F$2,1),出退勤入力!$A:$A,"<="&DATE(月次集計!$E$2,月次集計!$F$2+1,0),出退勤入力!$F:$F,"F") | P7: =IFERROR(VLOOKUP(A7,従業員マスタ!$A:$F,6,0),0) | Q7: =IFERROR(VLOOKUP(A7,従業員マスタ!$A:$G,7,0)*H7*1.25,0) | R7: 0 | S7: =IFERROR(P7+Q7+R7,0) | T7: =IFERROR(SUMIFS(出退勤入力!$M:$M,出退勤入力!$B:$B,A7,出退勤入力!$A:$A,">="&DATE($E$2,$F$2,1),出退勤入力!$A:$A,"<="&DATE($E$2,$F$2+1,0)),0)
A8: EMP006 | B8: =IFERROR(VLOOKUP(A8,従業員マスタ!$A:$B,2,0),"") | C8: =COUNTIFS(出退勤入力!$B:$B,A8,出退勤入力!$A:$A,">="&DATE(月次集計!$E$2,月次集計!$F$2,1),出退勤入力!$A:$A,"<="&DATE(月次集計!$E$2,月次集計!$F$2+1,0),出退勤入力!$E:$E,"○") | D8: =COUNTIFS(出退勤入力!$B:$B,A8,出退勤入力!$A:$A,">="&DATE(月次集計!$E$2,月次集計!$F$2,1),出退勤入力!$A:$A,"<="&DATE(月次集計!$E$2,月次集計!$F$2+1,0),出退勤入力!$E:$E,"△") | E8: =COUNTIFS(出退勤入力!$B:$B,A8,出退勤入力!$A:$A,">="&DATE(月次集計!$E$2,月次集計!$F$2,1),出退勤入力!$A:$A,"<="&DATE(月次集計!$E$2,月次集計!$F$2+1,0),出退勤入力!$E:$E,"有給") | F8: =COUNTIFS(出退勤入力!$B:$B,A8,出退勤入力!$A:$A,">="&DATE(月次集計!$E$2,月次集計!$F$2,1),出退勤入力!$A:$A,"<="&DATE(月次集計!$E$2,月次集計!$F$2+1,0),出退勤入力!$E:$E,"出") | G8: =COUNTIFS(出退勤入力!$B:$B,A8,出退勤入力!$A:$A,">="&DATE(月次集計!$E$2,月次集計!$F$2,1),出退勤入力!$A:$A,"<="&DATE(月次集計!$E$2,月次集計!$F$2+1,0),出退勤入力!$E:$E,"欠勤") | H8: =IFERROR(SUMIFS(出退勤入力!$J:$J,出退勤入力!$B:$B,A8,出退勤入力!$A:$A,">="&DATE(月次集計!$E$2,月次集計!$F$2,1),出退勤入力!$A:$A,"<="&DATE(月次集計!$E$2,月次集計!$F$2+1,0)),0) | I8: =IFERROR(SUMIFS(出退勤入力!$K:$K,出退勤入力!$B:$B,A8,出退勤入力!$A:$A,">="&DATE(月次集計!$E$2,月次集計!$F$2,1),出退勤入力!$A:$A,"<="&DATE(月次集計!$E$2,月次集計!$F$2+1,0)),0) | J8: =COUNTIFS(出退勤入力!$B:$B,A8,出退勤入力!$A:$A,">="&DATE(月次集計!$E$2,月次集計!$F$2,1),出退勤入力!$A:$A,"<="&DATE(月次集計!$E$2,月次集計!$F$2+1,0),出退勤入力!$F:$F,"A") | K8: =COUNTIFS(出退勤入力!$B:$B,A8,出退勤入力!$A:$A,">="&DATE(月次集計!$E$2,月次集計!$F$2,1),出退勤入力!$A:$A,"<="&DATE(月次集計!$E$2,月次集計!$F$2+1,0),出退勤入力!$F:$F,"B") | L8: =COUNTIFS(出退勤入力!$B:$B,A8,出退勤入力!$A:$A,">="&DATE(月次集計!$E$2,月次集計!$F$2,1),出退勤入力!$A:$A,"<="&DATE(月次集計!$E$2,月次集計!$F$2+1,0),出退勤入力!$F:$F,"C") | M8: =COUNTIFS(出退勤入力!$B:$B,A8,出退勤入力!$A:$A,">="&DATE(月次集計!$E$2,月次集計!$F$2,1),出退勤入力!$A:$A,"<="&DATE(月次集計!$E$2,月次集計!$F$2+1,0),出退勤入力!$F:$F,"D") | N8: =COUNTIFS(出退勤入力!$B:$B,A8,出退勤入力!$A:$A,">="&DATE(月次集計!$E$2,月次集計!$F$2,1),出退勤入力!$A:$A,"<="&DATE(月次集計!$E$2,月次集計!$F$2+1,0),出退勤入力!$F:$F,"E") | O8: =COUNTIFS(出退勤入力!$B:$B,A8,出退勤入力!$A:$A,">="&DATE(月次集計!$E$2,月次集計!$F$2,1),出退勤入力!$A:$A,"<="&DATE(月次集計!$E$2,月次集計!$F$2+1,0),出退勤入力!$F:$F,"F") | P8: =IFERROR(VLOOKUP(A8,従業員マスタ!$A:$F,6,0),0) | Q8: =IFERROR(VLOOKUP(A8,従業員マスタ!$A:$G,7,0)*H8*1.25,0) | R8: 0 | S8: =IFERROR(P8+Q8+R8,0) | T8: =IFERROR(SUMIFS(出退勤入力!$M:$M,出退勤入力!$B:$B,A8,出退勤入力!$A:$A,">="&DATE($E$2,$F$2,1),出退勤入力!$A:$A,"<="&DATE($E$2,$F$2+1,0)),0)
A9: EMP007 | B9: =IFERROR(VLOOKUP(A9,従業員マスタ!$A:$B,2,0),"") | C9: =COUNTIFS(出退勤入力!$B:$B,A9,出退勤入力!$A:$A,">="&DATE(月次集計!$E$2,月次集計!$F$2,1),出退勤入力!$A:$A,"<="&DATE(月次集計!$E$2,月次集計!$F$2+1,0),出退勤入力!$E:$E,"○") | D9: =COUNTIFS(出退勤入力!$B:$B,A9,出退勤入力!$A:$A,">="&DATE(月次集計!$E$2,月次集計!$F$2,1),出退勤入力!$A:$A,"<="&DATE(月次集計!$E$2,月次集計!$F$2+1,0),出退勤入力!$E:$E,"△") | E9: =COUNTIFS(出退勤入力!$B:$B,A9,出退勤入力!$A:$A,">="&DATE(月次集計!$E$2,月次集計!$F$2,1),出退勤入力!$A:$A,"<="&DATE(月次集計!$E$2,月次集計!$F$2+1,0),出退勤入力!$E:$E,"有給") | F9: =COUNTIFS(出退勤入力!$B:$B,A9,出退勤入力!$A:$A,">="&DATE(月次集計!$E$2,月次集計!$F$2,1),出退勤入力!$A:$A,"<="&DATE(月次集計!$E$2,月次集計!$F$2+1,0),出退勤入力!$E:$E,"出") | G9: =COUNTIFS(出退勤入力!$B:$B,A9,出退勤入力!$A:$A,">="&DATE(月次集計!$E$2,月次集計!$F$2,1),出退勤入力!$A:$A,"<="&DATE(月次集計!$E$2,月次集計!$F$2+1,0),出退勤入力!$E:$E,"欠勤") | H9: =IFERROR(SUMIFS(出退勤入力!$J:$J,出退勤入力!$B:$B,A9,出退勤入力!$A:$A,">="&DATE(月次集計!$E$2,月次集計!$F$2,1),出退勤入力!$A:$A,"<="&DATE(月次集計!$E$2,月次集計!$F$2+1,0)),0) | I9: =IFERROR(SUMIFS(出退勤入力!$K:$K,出退勤入力!$B:$B,A9,出退勤入力!$A:$A,">="&DATE(月次集計!$E$2,月次集計!$F$2,1),出退勤入力!$A:$A,"<="&DATE(月次集計!$E$2,月次集計!$F$2+1,0)),0) | J9: =COUNTIFS(出退勤入力!$B:$B,A9,出退勤入力!$A:$A,">="&DATE(月次集計!$E$2,月次集計!$F$2,1),出退勤入力!$A:$A,"<="&DATE(月次集計!$E$2,月次集計!$F$2+1,0),出退勤入力!$F:$F,"A") | K9: =COUNTIFS(出退勤入力!$B:$B,A9,出退勤入力!$A:$A,">="&DATE(月次集計!$E$2,月次集計!$F$2,1),出退勤入力!$A:$A,"<="&DATE(月次集計!$E$2,月次集計!$F$2+1,0),出退勤入力!$F:$F,"B") | L9: =COUNTIFS(出退勤入力!$B:$B,A9,出退勤入力!$A:$A,">="&DATE(月次集計!$E$2,月次集計!$F$2,1),出退勤入力!$A:$A,"<="&DATE(月次集計!$E$2,月次集計!$F$2+1,0),出退勤入力!$F:$F,"C") | M9: =COUNTIFS(出退勤入力!$B:$B,A9,出退勤入力!$A:$A,">="&DATE(月次集計!$E$2,月次集計!$F$2,1),出退勤入力!$A:$A,"<="&DATE(月次集計!$E$2,月次集計!$F$2+1,0),出退勤入力!$F:$F,"D") | N9: =COUNTIFS(出退勤入力!$B:$B,A9,出退勤入力!$A:$A,">="&DATE(月次集計!$E$2,月次集計!$F$2,1),出退勤入力!$A:$A,"<="&DATE(月次集計!$E$2,月次集計!$F$2+1,0),出退勤入力!$F:$F,"E") | O9: =COUNTIFS(出退勤入力!$B:$B,A9,出退勤入力!$A:$A,">="&DATE(月次集計!$E$2,月次集計!$F$2,1),出退勤入力!$A:$A,"<="&DATE(月次集計!$E$2,月次集計!$F$2+1,0),出退勤入力!$F:$F,"F") | P9: =IFERROR(VLOOKUP(A9,従業員マスタ!$A:$F,6,0),0) | Q9: =IFERROR(VLOOKUP(A9,従業員マスタ!$A:$G,7,0)*H9*1.25,0) | R9: 0 | S9: =IFERROR(P9+Q9+R9,0) | T9: =IFERROR(SUMIFS(出退勤入力!$M:$M,出退勤入力!$B:$B,A9,出退勤入力!$A:$A,">="&DATE($E$2,$F$2,1),出退勤入力!$A:$A,"<="&DATE($E$2,$F$2+1,0)),0)
A10: EMP008 | B10: =IFERROR(VLOOKUP(A10,従業員マスタ!$A:$B,2,0),"") | C10: =COUNTIFS(出退勤入力!$B:$B,A10,出退勤入力!$A:$A,">="&DATE(月次集計!$E$2,月次集計!$F$2,1),出退勤入力!$A:$A,"<="&DATE(月次集計!$E$2,月次集計!$F$2+1,0),出退勤入力!$E:$E,"○") | D10: =COUNTIFS(出退勤入力!$B:$B,A10,出退勤入力!$A:$A,">="&DATE(月次集計!$E$2,月次集計!$F$2,1),出退勤入力!$A:$A,"<="&DATE(月次集計!$E$2,月次集計!$F$2+1,0),出退勤入力!$E:$E,"△") | E10: =COUNTIFS(出退勤入力!$B:$B,A10,出退勤入力!$A:$A,">="&DATE(月次集計!$E$2,月次集計!$F$2,1),出退勤入力!$A:$A,"<="&DATE(月次集計!$E$2,月次集計!$F$2+1,0),出退勤入力!$E:$E,"有給") | F10: =COUNTIFS(出退勤入力!$B:$B,A10,出退勤入力!$A:$A,">="&DATE(月次集計!$E$2,月次集計!$F$2,1),出退勤入力!$A:$A,"<="&DATE(月次集計!$E$2,月次集計!$F$2+1,0),出退勤入力!$E:$E,"出") | G10: =COUNTIFS(出退勤入力!$B:$B,A10,出退勤入力!$A:$A,">="&DATE(月次集計!$E$2,月次集計!$F$2,1),出退勤入力!$A:$A,"<="&DATE(月次集計!$E$2,月次集計!$F$2+1,0),出退勤入力!$E:$E,"欠勤") | H10: =IFERROR(SUMIFS(出退勤入力!$J:$J,出退勤入力!$B:$B,A10,出退勤入力!$A:$A,">="&DATE(月次集計!$E$2,月次集計!$F$2,1),出退勤入力!$A:$A,"<="&DATE(月次集計!$E$2,月次集計!$F$2+1,0)),0) | I10: =IFERROR(SUMIFS(出退勤入力!$K:$K,出退勤入力!$B:$B,A10,出退勤入力!$A:$A,">="&DATE(月次集計!$E$2,月次集計!$F$2,1),出退勤入力!$A:$A,"<="&DATE(月次集計!$E$2,月次集計!$F$2+1,0)),0) | J10: =COUNTIFS(出退勤入力!$B:$B,A10,出退勤入力!$A:$A,">="&DATE(月次集計!$E$2,月次集計!$F$2,1),出退勤入力!$A:$A,"<="&DATE(月次集計!$E$2,月次集計!$F$2+1,0),出退勤入力!$F:$F,"A") | K10: =COUNTIFS(出退勤入力!$B:$B,A10,出退勤入力!$A:$A,">="&DATE(月次集計!$E$2,月次集計!$F$2,1),出退勤入力!$A:$A,"<="&DATE(月次集計!$E$2,月次集計!$F$2+1,0),出退勤入力!$F:$F,"B") | L10: =COUNTIFS(出退勤入力!$B:$B,A10,出退勤入力!$A:$A,">="&DATE(月次集計!$E$2,月次集計!$F$2,1),出退勤入力!$A:$A,"<="&DATE(月次集計!$E$2,月次集計!$F$2+1,0),出退勤入力!$F:$F,"C") | M10: =COUNTIFS(出退勤入力!$B:$B,A10,出退勤入力!$A:$A,">="&DATE(月次集計!$E$2,月次集計!$F$2,1),出退勤入力!$A:$A,"<="&DATE(月次集計!$E$2,月次集計!$F$2+1,0),出退勤入力!$F:$F,"D") | N10: =COUNTIFS(出退勤入力!$B:$B,A10,出退勤入力!$A:$A,">="&DATE(月次集計!$E$2,月次集計!$F$2,1),出退勤入力!$A:$A,"<="&DATE(月次集計!$E$2,月次集計!$F$2+1,0),出退勤入力!$F:$F,"E") | O10: =COUNTIFS(出退勤入力!$B:$B,A10,出退勤入力!$A:$A,">="&DATE(月次集計!$E$2,月次集計!$F$2,1),出退勤入力!$A:$A,"<="&DATE(月次集計!$E$2,月次集計!$F$2+1,0),出退勤入力!$F:$F,"F") | P10: =IFERROR(VLOOKUP(A10,従業員マスタ!$A:$F,6,0),0) | Q10: =IFERROR(VLOOKUP(A10,従業員マスタ!$A:$G,7,0)*H10*1.25,0) | R10: 0 | S10: =IFERROR(P10+Q10+R10,0) | T10: =IFERROR(SUMIFS(出退勤入力!$M:$M,出退勤入力!$B:$B,A10,出退勤入力!$A:$A,">="&DATE($E$2,$F$2,1),出退勤入力!$A:$A,"<="&DATE($E$2,$F$2+1,0)),0)
A11: EMP009 | B11: =IFERROR(VLOOKUP(A11,従業員マスタ!$A:$B,2,0),"") | C11: =COUNTIFS(出退勤入力!$B:$B,A11,出退勤入力!$A:$A,">="&DATE(月次集計!$E$2,月次集計!$F$2,1),出退勤入力!$A:$A,"<="&DATE(月次集計!$E$2,月次集計!$F$2+1,0),出退勤入力!$E:$E,"○") | D11: =COUNTIFS(出退勤入力!$B:$B,A11,出退勤入力!$A:$A,">="&DATE(月次集計!$E$2,月次集計!$F$2,1),出退勤入力!$A:$A,"<="&DATE(月次集計!$E$2,月次集計!$F$2+1,0),出退勤入力!$E:$E,"△") | E11: =COUNTIFS(出退勤入力!$B:$B,A11,出退勤入力!$A:$A,">="&DATE(月次集計!$E$2,月次集計!$F$2,1),出退勤入力!$A:$A,"<="&DATE(月次集計!$E$2,月次集計!$F$2+1,0),出退勤入力!$E:$E,"有給") | F11: =COUNTIFS(出退勤入力!$B:$B,A11,出退勤入力!$A:$A,">="&DATE(月次集計!$E$2,月次集計!$F$2,1),出退勤入力!$A:$A,"<="&DATE(月次集計!$E$2,月次集計!$F$2+1,0),出退勤入力!$E:$E,"出") | G11: =COUNTIFS(出退勤入力!$B:$B,A11,出退勤入力!$A:$A,">="&DATE(月次集計!$E$2,月次集計!$F$2,1),出退勤入力!$A:$A,"<="&DATE(月次集計!$E$2,月次集計!$F$2+1,0),出退勤入力!$E:$E,"欠勤") | H11: =IFERROR(SUMIFS(出退勤入力!$J:$J,出退勤入力!$B:$B,A11,出退勤入力!$A:$A,">="&DATE(月次集計!$E$2,月次集計!$F$2,1),出退勤入力!$A:$A,"<="&DATE(月次集計!$E$2,月次集計!$F$2+1,0)),0) | I11: =IFERROR(SUMIFS(出退勤入力!$K:$K,出退勤入力!$B:$B,A11,出退勤入力!$A:$A,">="&DATE(月次集計!$E$2,月次集計!$F$2,1),出退勤入力!$A:$A,"<="&DATE(月次集計!$E$2,月次集計!$F$2+1,0)),0) | J11: =COUNTIFS(出退勤入力!$B:$B,A11,出退勤入力!$A:$A,">="&DATE(月次集計!$E$2,月次集計!$F$2,1),出退勤入力!$A:$A,"<="&DATE(月次集計!$E$2,月次集計!$F$2+1,0),出退勤入力!$F:$F,"A") | K11: =COUNTIFS(出退勤入力!$B:$B,A11,出退勤入力!$A:$A,">="&DATE(月次集計!$E$2,月次集計!$F$2,1),出退勤入力!$A:$A,"<="&DATE(月次集計!$E$2,月次集計!$F$2+1,0),出退勤入力!$F:$F,"B") | L11: =COUNTIFS(出退勤入力!$B:$B,A11,出退勤入力!$A:$A,">="&DATE(月次集計!$E$2,月次集計!$F$2,1),出退勤入力!$A:$A,"<="&DATE(月次集計!$E$2,月次集計!$F$2+1,0),出退勤入力!$F:$F,"C") | M11: =COUNTIFS(出退勤入力!$B:$B,A11,出退勤入力!$A:$A,">="&DATE(月次集計!$E$2,月次集計!$F$2,1),出退勤入力!$A:$A,"<="&DATE(月次集計!$E$2,月次集計!$F$2+1,0),出退勤入力!$F:$F,"D") | N11: =COUNTIFS(出退勤入力!$B:$B,A11,出退勤入力!$A:$A,">="&DATE(月次集計!$E$2,月次集計!$F$2,1),出退勤入力!$A:$A,"<="&DATE(月次集計!$E$2,月次集計!$F$2+1,0),出退勤入力!$F:$F,"E") | O11: =COUNTIFS(出退勤入力!$B:$B,A11,出退勤入力!$A:$A,">="&DATE(月次集計!$E$2,月次集計!$F$2,1),出退勤入力!$A:$A,"<="&DATE(月次集計!$E$2,月次集計!$F$2+1,0),出退勤入力!$F:$F,"F") | P11: =IFERROR(VLOOKUP(A11,従業員マスタ!$A:$F,6,0),0) | Q11: =IFERROR(VLOOKUP(A11,従業員マスタ!$A:$G,7,0)*H11*1.25,0) | R11: 0 | S11: =IFERROR(P11+Q11+R11,0) | T11: =IFERROR(SUMIFS(出退勤入力!$M:$M,出退勤入力!$B:$B,A11,出退勤入力!$A:$A,">="&DATE($E$2,$F$2,1),出退勤入力!$A:$A,"<="&DATE($E$2,$F$2+1,0)),0)
A12: EMP010 | B12: =IFERROR(VLOOKUP(A12,従業員マスタ!$A:$B,2,0),"") | C12: =COUNTIFS(出退勤入力!$B:$B,A12,出退勤入力!$A:$A,">="&DATE(月次集計!$E$2,月次集計!$F$2,1),出退勤入力!$A:$A,"<="&DATE(月次集計!$E$2,月次集計!$F$2+1,0),出退勤入力!$E:$E,"○") | D12: =COUNTIFS(出退勤入力!$B:$B,A12,出退勤入力!$A:$A,">="&DATE(月次集計!$E$2,月次集計!$F$2,1),出退勤入力!$A:$A,"<="&DATE(月次集計!$E$2,月次集計!$F$2+1,0),出退勤入力!$E:$E,"△") | E12: =COUNTIFS(出退勤入力!$B:$B,A12,出退勤入力!$A:$A,">="&DATE(月次集計!$E$2,月次集計!$F$2,1),出退勤入力!$A:$A,"<="&DATE(月次集計!$E$2,月次集計!$F$2+1,0),出退勤入力!$E:$E,"有給") | F12: =COUNTIFS(出退勤入力!$B:$B,A12,出退勤入力!$A:$A,">="&DATE(月次集計!$E$2,月次集計!$F$2,1),出退勤入力!$A:$A,"<="&DATE(月次集計!$E$2,月次集計!$F$2+1,0),出退勤入力!$E:$E,"出") | G12: =COUNTIFS(出退勤入力!$B:$B,A12,出退勤入力!$A:$A,">="&DATE(月次集計!$E$2,月次集計!$F$2,1),出退勤入力!$A:$A,"<="&DATE(月次集計!$E$2,月次集計!$F$2+1,0),出退勤入力!$E:$E,"欠勤") | H12: =IFERROR(SUMIFS(出退勤入力!$J:$J,出退勤入力!$B:$B,A12,出退勤入力!$A:$A,">="&DATE(月次集計!$E$2,月次集計!$F$2,1),出退勤入力!$A:$A,"<="&DATE(月次集計!$E$2,月次集計!$F$2+1,0)),0) | I12: =IFERROR(SUMIFS(出退勤入力!$K:$K,出退勤入力!$B:$B,A12,出退勤入力!$A:$A,">="&DATE(月次集計!$E$2,月次集計!$F$2,1),出退勤入力!$A:$A,"<="&DATE(月次集計!$E$2,月次集計!$F$2+1,0)),0) | J12: =COUNTIFS(出退勤入力!$B:$B,A12,出退勤入力!$A:$A,">="&DATE(月次集計!$E$2,月次集計!$F$2,1),出退勤入力!$A:$A,"<="&DATE(月次集計!$E$2,月次集計!$F$2+1,0),出退勤入力!$F:$F,"A") | K12: =COUNTIFS(出退勤入力!$B:$B,A12,出退勤入力!$A:$A,">="&DATE(月次集計!$E$2,月次集計!$F$2,1),出退勤入力!$A:$A,"<="&DATE(月次集計!$E$2,月次集計!$F$2+1,0),出退勤入力!$F:$F,"B") | L12: =COUNTIFS(出退勤入力!$B:$B,A12,出退勤入力!$A:$A,">="&DATE(月次集計!$E$2,月次集計!$F$2,1),出退勤入力!$A:$A,"<="&DATE(月次集計!$E$2,月次集計!$F$2+1,0),出退勤入力!$F:$F,"C") | M12: =COUNTIFS(出退勤入力!$B:$B,A12,出退勤入力!$A:$A,">="&DATE(月次集計!$E$2,月次集計!$F$2,1),出退勤入力!$A:$A,"<="&DATE(月次集計!$E$2,月次集計!$F$2+1,0),出退勤入力!$F:$F,"D") | N12: =COUNTIFS(出退勤入力!$B:$B,A12,出退勤入力!$A:$A,">="&DATE(月次集計!$E$2,月次集計!$F$2,1),出退勤入力!$A:$A,"<="&DATE(月次集計!$E$2,月次集計!$F$2+1,0),出退勤入力!$F:$F,"E") | O12: =COUNTIFS(出退勤入力!$B:$B,A12,出退勤入力!$A:$A,">="&DATE(月次集計!$E$2,月次集計!$F$2,1),出退勤入力!$A:$A,"<="&DATE(月次集計!$E$2,月次集計!$F$2+1,0),出退勤入力!$F:$F,"F") | P12: =IFERROR(VLOOKUP(A12,従業員マスタ!$A:$F,6,0),0) | Q12: =IFERROR(VLOOKUP(A12,従業員マスタ!$A:$G,7,0)*H12*1.25,0) | R12: 0 | S12: =IFERROR(P12+Q12+R12,0) | T12: =IFERROR(SUMIFS(出退勤入力!$M:$M,出退勤入力!$B:$B,A12,出退勤入力!$A:$A,">="&DATE($E$2,$F$2,1),出退勤入力!$A:$A,"<="&DATE($E$2,$F$2+1,0)),0)
A13: EMP011 | B13: =IFERROR(VLOOKUP(A13,従業員マスタ!$A:$B,2,0),"") | C13: =COUNTIFS(出退勤入力!$B:$B,A13,出退勤入力!$A:$A,">="&DATE(月次集計!$E$2,月次集計!$F$2,1),出退勤入力!$A:$A,"<="&DATE(月次集計!$E$2,月次集計!$F$2+1,0),出退勤入力!$E:$E,"○") | D13: =COUNTIFS(出退勤入力!$B:$B,A13,出退勤入力!$A:$A,">="&DATE(月次集計!$E$2,月次集計!$F$2,1),出退勤入力!$A:$A,"<="&DATE(月次集計!$E$2,月次集計!$F$2+1,0),出退勤入力!$E:$E,"△") | E13: =COUNTIFS(出退勤入力!$B:$B,A13,出退勤入力!$A:$A,">="&DATE(月次集計!$E$2,月次集計!$F$2,1),出退勤入力!$A:$A,"<="&DATE(月次集計!$E$2,月次集計!$F$2+1,0),出退勤入力!$E:$E,"有給") | F13: =COUNTIFS(出退勤入力!$B:$B,A13,出退勤入力!$A:$A,">="&DATE(月次集計!$E$2,月次集計!$F$2,1),出退勤入力!$A:$A,"<="&DATE(月次集計!$E$2,月次集計!$F$2+1,0),出退勤入力!$E:$E,"出") | G13: =COUNTIFS(出退勤入力!$B:$B,A13,出退勤入力!$A:$A,">="&DATE(月次集計!$E$2,月次集計!$F$2,1),出退勤入力!$A:$A,"<="&DATE(月次集計!$E$2,月次集計!$F$2+1,0),出退勤入力!$E:$E,"欠勤") | H13: =IFERROR(SUMIFS(出退勤入力!$J:$J,出退勤入力!$B:$B,A13,出退勤入力!$A:$A,">="&DATE(月次集計!$E$2,月次集計!$F$2,1),出退勤入力!$A:$A,"<="&DATE(月次集計!$E$2,月次集計!$F$2+1,0)),0) | I13: =IFERROR(SUMIFS(出退勤入力!$K:$K,出退勤入力!$B:$B,A13,出退勤入力!$A:$A,">="&DATE(月次集計!$E$2,月次集計!$F$2,1),出退勤入力!$A:$A,"<="&DATE(月次集計!$E$2,月次集計!$F$2+1,0)),0) | J13: =COUNTIFS(出退勤入力!$B:$B,A13,出退勤入力!$A:$A,">="&DATE(月次集計!$E$2,月次集計!$F$2,1),出退勤入力!$A:$A,"<="&DATE(月次集計!$E$2,月次集計!$F$2+1,0),出退勤入力!$F:$F,"A") | K13: =COUNTIFS(出退勤入力!$B:$B,A13,出退勤入力!$A:$A,">="&DATE(月次集計!$E$2,月次集計!$F$2,1),出退勤入力!$A:$A,"<="&DATE(月次集計!$E$2,月次集計!$F$2+1,0),出退勤入力!$F:$F,"B") | L13: =COUNTIFS(出退勤入力!$B:$B,A13,出退勤入力!$A:$A,">="&DATE(月次集計!$E$2,月次集計!$F$2,1),出退勤入力!$A:$A,"<="&DATE(月次集計!$E$2,月次集計!$F$2+1,0),出退勤入力!$F:$F,"C") | M13: =COUNTIFS(出退勤入力!$B:$B,A13,出退勤入力!$A:$A,">="&DATE(月次集計!$E$2,月次集計!$F$2,1),出退勤入力!$A:$A,"<="&DATE(月次集計!$E$2,月次集計!$F$2+1,0),出退勤入力!$F:$F,"D") | N13: =COUNTIFS(出退勤入力!$B:$B,A13,出退勤入力!$A:$A,">="&DATE(月次集計!$E$2,月次集計!$F$2,1),出退勤入力!$A:$A,"<="&DATE(月次集計!$E$2,月次集計!$F$2+1,0),出退勤入力!$F:$F,"E") | O13: =COUNTIFS(出退勤入力!$B:$B,A13,出退勤入力!$A:$A,">="&DATE(月次集計!$E$2,月次集計!$F$2,1),出退勤入力!$A:$A,"<="&DATE(月次集計!$E$2,月次集計!$F$2+1,0),出退勤入力!$F:$F,"F") | P13: =IFERROR(VLOOKUP(A13,従業員マスタ!$A:$F,6,0),0) | Q13: =IFERROR(VLOOKUP(A13,従業員マスタ!$A:$G,7,0)*H13*1.25,0) | R13: 0 | S13: =IFERROR(P13+Q13+R13,0) | T13: =IFERROR(SUMIFS(出退勤入力!$M:$M,出退勤入力!$B:$B,A13,出退勤入力!$A:$A,">="&DATE($E$2,$F$2,1),出退勤入力!$A:$A,"<="&DATE($E$2,$F$2+1,0)),0)
A14: EMP012 | B14: =IFERROR(VLOOKUP(A14,従業員マスタ!$A:$B,2,0),"") | C14: =COUNTIFS(出退勤入力!$B:$B,A14,出退勤入力!$A:$A,">="&DATE(月次集計!$E$2,月次集計!$F$2,1),出退勤入力!$A:$A,"<="&DATE(月次集計!$E$2,月次集計!$F$2+1,0),出退勤入力!$E:$E,"○") | D14: =COUNTIFS(出退勤入力!$B:$B,A14,出退勤入力!$A:$A,">="&DATE(月次集計!$E$2,月次集計!$F$2,1),出退勤入力!$A:$A,"<="&DATE(月次集計!$E$2,月次集計!$F$2+1,0),出退勤入力!$E:$E,"△") | E14: =COUNTIFS(出退勤入力!$B:$B,A14,出退勤入力!$A:$A,">="&DATE(月次集計!$E$2,月次集計!$F$2,1),出退勤入力!$A:$A,"<="&DATE(月次集計!$E$2,月次集計!$F$2+1,0),出退勤入力!$E:$E,"有給") | F14: =COUNTIFS(出退勤入力!$B:$B,A14,出退勤入力!$A:$A,">="&DATE(月次集計!$E$2,月次集計!$F$2,1),出退勤入力!$A:$A,"<="&DATE(月次集計!$E$2,月次集計!$F$2+1,0),出退勤入力!$E:$E,"出") | G14: =COUNTIFS(出退勤入力!$B:$B,A14,出退勤入力!$A:$A,">="&DATE(月次集計!$E$2,月次集計!$F$2,1),出退勤入力!$A:$A,"<="&DATE(月次集計!$E$2,月次集計!$F$2+1,0),出退勤入力!$E:$E,"欠勤") | H14: =IFERROR(SUMIFS(出退勤入力!$J:$J,出退勤入力!$B:$B,A14,出退勤入力!$A:$A,">="&DATE(月次集計!$E$2,月次集計!$F$2,1),出退勤入力!$A:$A,"<="&DATE(月次集計!$E$2,月次集計!$F$2+1,0)),0) | I14: =IFERROR(SUMIFS(出退勤入力!$K:$K,出退勤入力!$B:$B,A14,出退勤入力!$A:$A,">="&DATE(月次集計!$E$2,月次集計!$F$2,1),出退勤入力!$A:$A,"<="&DATE(月次集計!$E$2,月次集計!$F$2+1,0)),0) | J14: =COUNTIFS(出退勤入力!$B:$B,A14,出退勤入力!$A:$A,">="&DATE(月次集計!$E$2,月次集計!$F$2,1),出退勤入力!$A:$A,"<="&DATE(月次集計!$E$2,月次集計!$F$2+1,0),出退勤入力!$F:$F,"A") | K14: =COUNTIFS(出退勤入力!$B:$B,A14,出退勤入力!$A:$A,">="&DATE(月次集計!$E$2,月次集計!$F$2,1),出退勤入力!$A:$A,"<="&DATE(月次集計!$E$2,月次集計!$F$2+1,0),出退勤入力!$F:$F,"B") | L14: =COUNTIFS(出退勤入力!$B:$B,A14,出退勤入力!$A:$A,">="&DATE(月次集計!$E$2,月次集計!$F$2,1),出退勤入力!$A:$A,"<="&DATE(月次集計!$E$2,月次集計!$F$2+1,0),出退勤入力!$F:$F,"C") | M14: =COUNTIFS(出退勤入力!$B:$B,A14,出退勤入力!$A:$A,">="&DATE(月次集計!$E$2,月次集計!$F$2,1),出退勤入力!$A:$A,"<="&DATE(月次集計!$E$2,月次集計!$F$2+1,0),出退勤入力!$F:$F,"D") | N14: =COUNTIFS(出退勤入力!$B:$B,A14,出退勤入力!$A:$A,">="&DATE(月次集計!$E$2,月次集計!$F$2,1),出退勤入力!$A:$A,"<="&DATE(月次集計!$E$2,月次集計!$F$2+1,0),出退勤入力!$F:$F,"E") | O14: =COUNTIFS(出退勤入力!$B:$B,A14,出退勤入力!$A:$A,">="&DATE(月次集計!$E$2,月次集計!$F$2,1),出退勤入力!$A:$A,"<="&DATE(月次集計!$E$2,月次集計!$F$2+1,0),出退勤入力!$F:$F,"F") | P14: =IFERROR(VLOOKUP(A14,従業員マスタ!$A:$F,6,0),0) | Q14: =IFERROR(VLOOKUP(A14,従業員マスタ!$A:$G,7,0)*H14*1.25,0) | R14: 0 | S14: =IFERROR(P14+Q14+R14,0) | T14: =IFERROR(SUMIFS(出退勤入力!$M:$M,出退勤入力!$B:$B,A14,出退勤入力!$A:$A,">="&DATE($E$2,$F$2,1),出退勤入力!$A:$A,"<="&DATE($E$2,$F$2+1,0)),0)
A15: EMP013 | B15: =IFERROR(VLOOKUP(A15,従業員マスタ!$A:$B,2,0),"") | C15: =COUNTIFS(出退勤入力!$B:$B,A15,出退勤入力!$A:$A,">="&DATE(月次集計!$E$2,月次集計!$F$2,1),出退勤入力!$A:$A,"<="&DATE(月次集計!$E$2,月次集計!$F$2+1,0),出退勤入力!$E:$E,"○") | D15: =COUNTIFS(出退勤入力!$B:$B,A15,出退勤入力!$A:$A,">="&DATE(月次集計!$E$2,月次集計!$F$2,1),出退勤入力!$A:$A,"<="&DATE(月次集計!$E$2,月次集計!$F$2+1,0),出退勤入力!$E:$E,"△") | E15: =COUNTIFS(出退勤入力!$B:$B,A15,出退勤入力!$A:$A,">="&DATE(月次集計!$E$2,月次集計!$F$2,1),出退勤入力!$A:$A,"<="&DATE(月次集計!$E$2,月次集計!$F$2+1,0),出退勤入力!$E:$E,"有給") | F15: =COUNTIFS(出退勤入力!$B:$B,A15,出退勤入力!$A:$A,">="&DATE(月次集計!$E$2,月次集計!$F$2,1),出退勤入力!$A:$A,"<="&DATE(月次集計!$E$2,月次集計!$F$2+1,0),出退勤入力!$E:$E,"出") | G15: =COUNTIFS(出退勤入力!$B:$B,A15,出退勤入力!$A:$A,">="&DATE(月次集計!$E$2,月次集計!$F$2,1),出退勤入力!$A:$A,"<="&DATE(月次集計!$E$2,月次集計!$F$2+1,0),出退勤入力!$E:$E,"欠勤") | H15: =IFERROR(SUMIFS(出退勤入力!$J:$J,出退勤入力!$B:$B,A15,出退勤入力!$A:$A,">="&DATE(月次集計!$E$2,月次集計!$F$2,1),出退勤入力!$A:$A,"<="&DATE(月次集計!$E$2,月次集計!$F$2+1,0)),0) | I15: =IFERROR(SUMIFS(出退勤入力!$K:$K,出退勤入力!$B:$B,A15,出退勤入力!$A:$A,">="&DATE(月次集計!$E$2,月次集計!$F$2,1),出退勤入力!$A:$A,"<="&DATE(月次集計!$E$2,月次集計!$F$2+1,0)),0) | J15: =COUNTIFS(出退勤入力!$B:$B,A15,出退勤入力!$A:$A,">="&DATE(月次集計!$E$2,月次集計!$F$2,1),出退勤入力!$A:$A,"<="&DATE(月次集計!$E$2,月次集計!$F$2+1,0),出退勤入力!$F:$F,"A") | K15: =COUNTIFS(出退勤入力!$B:$B,A15,出退勤入力!$A:$A,">="&DATE(月次集計!$E$2,月次集計!$F$2,1),出退勤入力!$A:$A,"<="&DATE(月次集計!$E$2,月次集計!$F$2+1,0),出退勤入力!$F:$F,"B") | L15: =COUNTIFS(出退勤入力!$B:$B,A15,出退勤入力!$A:$A,">="&DATE(月次集計!$E$2,月次集計!$F$2,1),出退勤入力!$A:$A,"<="&DATE(月次集計!$E$2,月次集計!$F$2+1,0),出退勤入力!$F:$F,"C") | M15: =COUNTIFS(出退勤入力!$B:$B,A15,出退勤入力!$A:$A,">="&DATE(月次集計!$E$2,月次集計!$F$2,1),出退勤入力!$A:$A,"<="&DATE(月次集計!$E$2,月次集計!$F$2+1,0),出退勤入力!$F:$F,"D") | N15: =COUNTIFS(出退勤入力!$B:$B,A15,出退勤入力!$A:$A,">="&DATE(月次集計!$E$2,月次集計!$F$2,1),出退勤入力!$A:$A,"<="&DATE(月次集計!$E$2,月次集計!$F$2+1,0),出退勤入力!$F:$F,"E") | O15: =COUNTIFS(出退勤入力!$B:$B,A15,出退勤入力!$A:$A,">="&DATE(月次集計!$E$2,月次集計!$F$2,1),出退勤入力!$A:$A,"<="&DATE(月次集計!$E$2,月次集計!$F$2+1,0),出退勤入力!$F:$F,"F") | P15: =IFERROR(VLOOKUP(A15,従業員マスタ!$A:$F,6,0),0) | Q15: =IFERROR(VLOOKUP(A15,従業員マスタ!$A:$G,7,0)*H15*1.25,0) | R15: 0 | S15: =IFERROR(P15+Q15+R15,0) | T15: =IFERROR(SUMIFS(出退勤入力!$M:$M,出退勤入力!$B:$B,A15,出退勤入力!$A:$A,">="&DATE($E$2,$F$2,1),出退勤入力!$A:$A,"<="&DATE($E$2,$F$2+1,0)),0)
... A19: EMP017 | B19: =IFERROR(VLOOKUP(A19,従業員マスタ!$A:$B,2,0),"") | C19: =COUNTIFS(出退勤入力!$B:$B,A19,出退勤入力!$A:$A,">="&DATE(月次集計!$E$2,月次集計!$F$2,1),出退勤入力!$A:$A,"<="&DATE(月次集計!$E$2,月次集計!$F$2+1,0),出退勤入力!$E:$E,"○") | D19: =COUNTIFS(出退勤入力!$B:$B,A19,出退勤入力!$A:$A,">="&DATE(月次集計!$E$2,月次集計!$F$2,1),出退勤入力!$A:$A,"<="&DATE(月次集計!$E$2,月次集計!$F$2+1,0),出退勤入力!$E:$E,"△") | E19: =COUNTIFS(出退勤入力!$B:$B,A19,出退勤入力!$A:$A,">="&DATE(月次集計!$E$2,月次集計!$F$2,1),出退勤入力!$A:$A,"<="&DATE(月次集計!$E$2,月次集計!$F$2+1,0),出退勤入力!$E:$E,"有給") | F19: =COUNTIFS(出退勤入力!$B:$B,A19,出退勤入力!$A:$A,">="&DATE(月次集計!$E$2,月次集計!$F$2,1),出退勤入力!$A:$A,"<="&DATE(月次集計!$E$2,月次集計!$F$2+1,0),出退勤入力!$E:$E,"出") | G19: =COUNTIFS(出退勤入力!$B:$B,A19,出退勤入力!$A:$A,">="&DATE(月次集計!$E$2,月次集計!$F$2,1),出退勤入力!$A:$A,"<="&DATE(月次集計!$E$2,月次集計!$F$2+1,0),出退勤入力!$E:$E,"欠勤") | H19: =IFERROR(SUMIFS(出退勤入力!$J:$J,出退勤入力!$B:$B,A19,出退勤入力!$A:$A,">="&DATE(月次集計!$E$2,月次集計!$F$2,1),出退勤入力!$A:$A,"<="&DATE(月次集計!$E$2,月次集計!$F$2+1,0)),0) | I19: =IFERROR(SUMIFS(出退勤入力!$K:$K,出退勤入力!$B:$B,A19,出退勤入力!$A:$A,">="&DATE(月次集計!$E$2,月次集計!$F$2,1),出退勤入力!$A:$A,"<="&DATE(月次集計!$E$2,月次集計!$F$2+1,0)),0) | J19: =COUNTIFS(出退勤入力!$B:$B,A19,出退勤入力!$A:$A,">="&DATE(月次集計!$E$2,月次集計!$F$2,1),出退勤入力!$A:$A,"<="&DATE(月次集計!$E$2,月次集計!$F$2+1,0),出退勤入力!$F:$F,"A") | K19: =COUNTIFS(出退勤入力!$B:$B,A19,出退勤入力!$A:$A,">="&DATE(月次集計!$E$2,月次集計!$F$2,1),出退勤入力!$A:$A,"<="&DATE(月次集計!$E$2,月次集計!$F$2+1,0),出退勤入力!$F:$F,"B") | L19: =COUNTIFS(出退勤入力!$B:$B,A19,出退勤入力!$A:$A,">="&DATE(月次集計!$E$2,月次集計!$F$2,1),出退勤入力!$A:$A,"<="&DATE(月次集計!$E$2,月次集計!$F$2+1,0),出退勤入力!$F:$F,"C") | M19: =COUNTIFS(出退勤入力!$B:$B,A19,出退勤入力!$A:$A,">="&DATE(月次集計!$E$2,月次集計!$F$2,1),出退勤入力!$A:$A,"<="&DATE(月次集計!$E$2,月次集計!$F$2+1,0),出退勤入力!$F:$F,"D") | N19: =COUNTIFS(出退勤入力!$B:$B,A19,出退勤入力!$A:$A,">="&DATE(月次集計!$E$2,月次集計!$F$2,1),出退勤入力!$A:$A,"<="&DATE(月次集計!$E$2,月次集計!$F$2+1,0),出退勤入力!$F:$F,"E") | O19: =COUNTIFS(出退勤入力!$B:$B,A19,出退勤入力!$A:$A,">="&DATE(月次集計!$E$2,月次集計!$F$2,1),出退勤入力!$A:$A,"<="&DATE(月次集計!$E$2,月次集計!$F$2+1,0),出退勤入力!$F:$F,"F") | P19: =IFERROR(VLOOKUP(A19,従業員マスタ!$A:$F,6,0),0) | Q19: =IFERROR(VLOOKUP(A19,従業員マスタ!$A:$G,7,0)*H19*1.25,0) | R19: 0 | S19: =IFERROR(P19+Q19+R19,0) | T19: =IFERROR(SUMIFS(出退勤入力!$M:$M,出退勤入力!$B:$B,A19,出退勤入力!$A:$A,">="&DATE($E$2,$F$2,1),出退勤入力!$A:$A,"<="&DATE($E$2,$F$2+1,0)),0)
A20: 合 計 | C20: =SUM(C4:C19) | D20: =SUM(D4:D19) | E20: =SUM(E4:E19) | F20: =SUM(F4:F19) | G20: =SUM(G4:G19) | H20: =SUM(H4:H19) | I20: =SUM(I4:I19) | J20: =SUM(J4:J19) | ... T20: =SUM(T4:T19)

Sheet 給与計算
A1: 給与計算書 有限会社 東輝
A2: 集計年月: | C2: =月次集計!C2 | D2: 支払日: 翌月2日 ※月次集計シートの年月と連動します
A3: 社員ID | B3: 氏名 | C3: 雇用区分 | D3: 基本給 /月給 | E3: 出勤 日数 | F3: 残業 時間 | G3: 有給 日数 | H3: 基本給 支給額 | I3: 残業 手当 | J3: 手当 合計 | K3: 欠勤 控除 | L3: 総支給 | M3: 健康 保険 | N3: 厚生 年金 | O3: 雇用 保険 | P3: 所得税 | Q3: 控除後支給額 (住民税前) | R3: 住民税 (固定月額) | S3: 友愛会費 | T3: ★立替金 (手動入力) | U3: 手取金額 (最終)
A4: EMP001 | B4: =IFERROR(VLOOKUP(A4,従業員マスタ!$A:$B,2,0),"") | C4: =IFERROR(VLOOKUP(A4,従業員マスタ!$A:$D,4,0),"") | D4: =IFERROR(VLOOKUP(A4,従業員マスタ!$A:$F,6,0),0) | E4: =IFERROR(VLOOKUP(A4,月次集計!$A:$C,3,0),0) | F4: =IFERROR(VLOOKUP(A4,月次集計!$A:$H,8,0),0) | G4: =IFERROR(VLOOKUP(A4,月次集計!$A:$E,5,0),0) | H4: =IF(C4="月給",D4,IF(C4="日給",D4*E4+IFERROR(VLOOKUP(A4,従業員マスタ!$A:$G,7,0),0)*G4*8,IF(C4="時給",IFERROR(VLOOKUP(A4,従業員マスタ!$A:$G,7,0)*(IFERROR(VLOOKUP(A4,月次集計!$A:$T,20,0),0)+G4*5),0),0))) | I4: =IF(OR(A4="EMP001",A4="EMP002"),0,IF(C4="時給",0,IFERROR(VLOOKUP(A4,従業員マスタ!$A:$G,7,0)*F4*1.25,0))) | J4: 0 | K4: =IF(OR(A4="EMP008",A4="EMP009",A4="EMP010",A4="EMP011",A4="EMP012",A4="EMP016"),IFERROR(VLOOKUP(A4,従業員マスタ!$A:$G,7,0)*(VLOOKUP(A4,月次集計!$A:$G,7,0)*8+VLOOKUP(A4,月次集計!$A:$I,9,0)),0),0) | L4: =H4+I4+J4-K4 | M4: =IFERROR(VLOOKUP(A4,従業員マスタ!$A:$I,8,0),0) | N4: =IFERROR(VLOOKUP(A4,従業員マスタ!$A:$J,9,0),0) | O4: =IFERROR(ROUND(L4*VLOOKUP(A4,従業員マスタ!$A:$K,10,0),0),0) | P4: =IFERROR(VLOOKUP(A4,従業員マスタ!$A:$L,11,0),0) | Q4: =L4-M4-N4-O4-P4 | R4: =IFERROR(VLOOKUP(A4,従業員マスタ!$A:$L,12,0),0) | S4: =IFERROR(VLOOKUP(A4,従業員マスタ!$A:$M,13,0),0) | T4: 0 | U4: =Q4-R4-S4-T4
A5: EMP002 | B5: =IFERROR(VLOOKUP(A5,従業員マスタ!$A:$B,2,0),"") | C5: =IFERROR(VLOOKUP(A5,従業員マスタ!$A:$D,4,0),"") | D5: =IFERROR(VLOOKUP(A5,従業員マスタ!$A:$F,6,0),0) | E5: =IFERROR(VLOOKUP(A5,月次集計!$A:$C,3,0),0) | F5: =IFERROR(VLOOKUP(A5,月次集計!$A:$H,8,0),0) | G5: =IFERROR(VLOOKUP(A5,月次集計!$A:$E,5,0),0) | H5: =IF(C5="月給",D5,IF(C5="日給",D5*E5+IFERROR(VLOOKUP(A5,従業員マスタ!$A:$G,7,0),0)*G5*8,IF(C5="時給",IFERROR(VLOOKUP(A5,従業員マスタ!$A:$G,7,0)*(IFERROR(VLOOKUP(A5,月次集計!$A:$T,20,0),0)+G5*5),0),0))) | I5: =IF(OR(A5="EMP001",A5="EMP002"),0,IF(C5="時給",0,IFERROR(VLOOKUP(A5,従業員マスタ!$A:$G,7,0)*F5*1.25,0))) | J5: 0 | K5: =IF(OR(A5="EMP008",A5="EMP009",A5="EMP010",A5="EMP011",A5="EMP012",A5="EMP016"),IFERROR(VLOOKUP(A5,従業員マスタ!$A:$G,7,0)*(VLOOKUP(A5,月次集計!$A:$G,7,0)*8+VLOOKUP(A5,月次集計!$A:$I,9,0)),0),0) | L5: =H5+I5+J5-K5 | M5: =IFERROR(VLOOKUP(A5,従業員マスタ!$A:$I,8,0),0) | N5: =IFERROR(VLOOKUP(A5,従業員マスタ!$A:$J,9,0),0) | O5: =IFERROR(ROUND(L5*VLOOKUP(A5,従業員マスタ!$A:$K,10,0),0),0) | P5: =IFERROR(VLOOKUP(A5,従業員マスタ!$A:$L,11,0),0) | Q5: =L5-M5-N5-O5-P5 | R5: =IFERROR(VLOOKUP(A5,従業員マスタ!$A:$L,12,0),0) | S5: =IFERROR(VLOOKUP(A5,従業員マスタ!$A:$M,13,0),0) | T5: 0 | U5: =Q5-R5-S5-T5
A6: EMP003 | B6: =IFERROR(VLOOKUP(A6,従業員マスタ!$A:$B,2,0),"") | C6: =IFERROR(VLOOKUP(A6,従業員マスタ!$A:$D,4,0),"") | D6: =IFERROR(VLOOKUP(A6,従業員マスタ!$A:$F,6,0),0) | E6: =IFERROR(VLOOKUP(A6,月次集計!$A:$C,3,0),0) | F6: =IFERROR(VLOOKUP(A6,月次集計!$A:$H,8,0),0) | G6: =IFERROR(VLOOKUP(A6,月次集計!$A:$E,5,0),0) | H6: =IF(C6="月給",D6,IF(C6="日給",D6*E6+IFERROR(VLOOKUP(A6,従業員マスタ!$A:$G,7,0),0)*G6*8,IF(C6="時給",IFERROR(VLOOKUP(A6,従業員マスタ!$A:$G,7,0)*(IFERROR(VLOOKUP(A6,月次集計!$A:$T,20,0),0)+G6*5),0),0))) | I6: =IF(OR(A6="EMP001",A6="EMP002"),0,IF(C6="時給",0,IFERROR(VLOOKUP(A6,従業員マスタ!$A:$G,7,0)*F6*1.25,0))) | J6: 0 | K6: =IF(OR(A6="EMP008",A6="EMP009",A6="EMP010",A6="EMP011",A6="EMP012",A6="EMP016"),IFERROR(VLOOKUP(A6,従業員マスタ!$A:$G,7,0)*(VLOOKUP(A6,月次集計!$A:$G,7,0)*8+VLOOKUP(A6,月次集計!$A:$I,9,0)),0),0) | L6: =H6+I6+J6-K6 | M6: =IFERROR(VLOOKUP(A6,従業員マスタ!$A:$I,8,0),0) | N6: =IFERROR(VLOOKUP(A6,従業員マスタ!$A:$J,9,0),0) | O6: =IFERROR(ROUND(L6*VLOOKUP(A6,従業員マスタ!$A:$K,10,0),0),0) | P6: =IFERROR(VLOOKUP(A6,従業員マスタ!$A:$L,11,0),0) | Q6: =L6-M6-N6-O6-P6 | R6: =IFERROR(VLOOKUP(A6,従業員マスタ!$A:$L,12,0),0) | S6: =IFERROR(VLOOKUP(A6,従業員マスタ!$A:$M,13,0),0) | T6: 0 | U6: =Q6-R6-S6-T6
A7: EMP004 | B7: =IFERROR(VLOOKUP(A7,従業員マスタ!$A:$B,2,0),"") | C7: =IFERROR(VLOOKUP(A7,従業員マスタ!$A:$D,4,0),"") | D7: =IFERROR(VLOOKUP(A7,従業員マスタ!$A:$F,6,0),0) | E7: =IFERROR(VLOOKUP(A7,月次集計!$A:$C,3,0),0) | F7: =IFERROR(VLOOKUP(A7,月次集計!$A:$H,8,0),0) | G7: =IFERROR(VLOOKUP(A7,月次集計!$A:$E,5,0),0) | H7: =IF(C7="月給",D7,IF(C7="日給",D7*E7+IFERROR(VLOOKUP(A7,従業員マスタ!$A:$G,7,0),0)*G7*8,IF(C7="時給",IFERROR(VLOOKUP(A7,従業員マスタ!$A:$G,7,0)*(IFERROR(VLOOKUP(A7,月次集計!$A:$T,20,0),0)+G7*5),0),0))) | I7: =IF(OR(A7="EMP001",A7="EMP002"),0,IF(C7="時給",0,IFERROR(VLOOKUP(A7,従業員マスタ!$A:$G,7,0)*F7*1.25,0))) | J7: 0 | K7: =IF(OR(A7="EMP008",A7="EMP009",A7="EMP010",A7="EMP011",A7="EMP012",A7="EMP016"),IFERROR(VLOOKUP(A7,従業員マスタ!$A:$G,7,0)*(VLOOKUP(A7,月次集計!$A:$G,7,0)*8+VLOOKUP(A7,月次集計!$A:$I,9,0)),0),0) | L7: =H7+I7+J7-K7 | M7: =IFERROR(VLOOKUP(A7,従業員マスタ!$A:$I,8,0),0) | N7: =IFERROR(VLOOKUP(A7,従業員マスタ!$A:$J,9,0),0) | O7: =IFERROR(ROUND(L7*VLOOKUP(A7,従業員マスタ!$A:$K,10,0),0),0) | P7: =IFERROR(VLOOKUP(A7,従業員マスタ!$A:$L,11,0),0) | Q7: =L7-M7-N7-O7-P7 | R7: =IFERROR(VLOOKUP(A7,従業員マスタ!$A:$L,12,0),0) | S7: =IFERROR(VLOOKUP(A7,従業員マスタ!$A:$M,13,0),0) | T7: 0 | U7: =Q7-R7-S7-T7
A8: EMP006 | B8: =IFERROR(VLOOKUP(A8,従業員マスタ!$A:$B,2,0),"") | C8: =IFERROR(VLOOKUP(A8,従業員マスタ!$A:$D,4,0),"") | D8: =IFERROR(VLOOKUP(A8,従業員マスタ!$A:$F,6,0),0) | E8: =IFERROR(VLOOKUP(A8,月次集計!$A:$C,3,0),0) | F8: =IFERROR(VLOOKUP(A8,月次集計!$A:$H,8,0),0) | G8: =IFERROR(VLOOKUP(A8,月次集計!$A:$E,5,0),0) | H8: =IF(C8="月給",D8,IF(C8="日給",D8*E8+IFERROR(VLOOKUP(A8,従業員マスタ!$A:$G,7,0),0)*G8*8,IF(C8="時給",IFERROR(VLOOKUP(A8,従業員マスタ!$A:$G,7,0)*(IFERROR(VLOOKUP(A8,月次集計!$A:$T,20,0),0)+G8*5),0),0))) | I8: =IF(OR(A8="EMP001",A8="EMP002"),0,IF(C8="時給",0,IFERROR(VLOOKUP(A8,従業員マスタ!$A:$G,7,0)*F8*1.25,0))) | J8: 0 | K8: =IF(OR(A8="EMP008",A8="EMP009",A8="EMP010",A8="EMP011",A8="EMP012",A8="EMP016"),IFERROR(VLOOKUP(A8,従業員マスタ!$A:$G,7,0)*(VLOOKUP(A8,月次集計!$A:$G,7,0)*8+VLOOKUP(A8,月次集計!$A:$I,9,0)),0),0) | L8: =H8+I8+J8-K8 | M8: =IFERROR(VLOOKUP(A8,従業員マスタ!$A:$I,8,0),0) | N8: =IFERROR(VLOOKUP(A8,従業員マスタ!$A:$J,9,0),0) | O8: =IFERROR(ROUND(L8*VLOOKUP(A8,従業員マスタ!$A:$K,10,0),0),0) | P8: =IFERROR(VLOOKUP(A8,従業員マスタ!$A:$L,11,0),0) | Q8: =L8-M8-N8-O8-P8 | R8: =IFERROR(VLOOKUP(A8,従業員マスタ!$A:$L,12,0),0) | S8: =IFERROR(VLOOKUP(A8,従業員マスタ!$A:$M,13,0),0) | T8: 0 | U8: =Q8-R8-S8-T8
A9: EMP007 | B9: =IFERROR(VLOOKUP(A9,従業員マスタ!$A:$B,2,0),"") | C9: =IFERROR(VLOOKUP(A9,従業員マスタ!$A:$D,4,0),"") | D9: =IFERROR(VLOOKUP(A9,従業員マスタ!$A:$F,6,0),0) | E9: =IFERROR(VLOOKUP(A9,月次集計!$A:$C,3,0),0) | F9: =IFERROR(VLOOKUP(A9,月次集計!$A:$H,8,0),0) | G9: =IFERROR(VLOOKUP(A9,月次集計!$A:$E,5,0),0) | H9: =IF(C9="月給",D9,IF(C9="日給",D9*E9+IFERROR(VLOOKUP(A9,従業員マスタ!$A:$G,7,0),0)*G9*8,IF(C9="時給",IFERROR(VLOOKUP(A9,従業員マスタ!$A:$G,7,0)*(IFERROR(VLOOKUP(A9,月次集計!$A:$T,20,0),0)+G9*5),0),0))) | I9: =IF(OR(A9="EMP001",A9="EMP002"),0,IF(C9="時給",0,IFERROR(VLOOKUP(A9,従業員マスタ!$A:$G,7,0)*F9*1.25,0))) | J9: 0 | K9: =IF(OR(A9="EMP008",A9="EMP009",A9="EMP010",A9="EMP011",A9="EMP012",A9="EMP016"),IFERROR(VLOOKUP(A9,従業員マスタ!$A:$G,7,0)*(VLOOKUP(A9,月次集計!$A:$G,7,0)*8+VLOOKUP(A9,月次集計!$A:$I,9,0)),0),0) | L9: =H9+I9+J9-K9 | M9: =IFERROR(VLOOKUP(A9,従業員マスタ!$A:$I,8,0),0) | N9: =IFERROR(VLOOKUP(A9,従業員マスタ!$A:$J,9,0),0) | O9: =IFERROR(ROUND(L9*VLOOKUP(A9,従業員マスタ!$A:$K,10,0),0),0) | P9: =IFERROR(VLOOKUP(A9,従業員マスタ!$A:$L,11,0),0) | Q9: =L9-M9-N9-O9-P9 | R9: =IFERROR(VLOOKUP(A9,従業員マスタ!$A:$L,12,0),0) | S9: =IFERROR(VLOOKUP(A9,従業員マスタ!$A:$M,13,0),0) | T9: 0 | U9: =Q9-R9-S9-T9
A10: EMP008 | B10: =IFERROR(VLOOKUP(A10,従業員マスタ!$A:$B,2,0),"") | C10: =IFERROR(VLOOKUP(A10,従業員マスタ!$A:$D,4,0),"") | D10: =IFERROR(VLOOKUP(A10,従業員マスタ!$A:$F,6,0),0) | E10: =IFERROR(VLOOKUP(A10,月次集計!$A:$C,3,0),0) | F10: =IFERROR(VLOOKUP(A10,月次集計!$A:$H,8,0),0) | G10: =IFERROR(VLOOKUP(A10,月次集計!$A:$E,5,0),0) | H10: =IF(C10="月給",D10,IF(C10="日給",D10*E10+IFERROR(VLOOKUP(A10,従業員マスタ!$A:$G,7,0),0)*G10*8,IF(C10="時給",IFERROR(VLOOKUP(A10,従業員マスタ!$A:$G,7,0)*(IFERROR(VLOOKUP(A10,月次集計!$A:$T,20,0),0)+G10*5),0),0))) | I10: =IF(OR(A10="EMP001",A10="EMP002"),0,IF(C10="時給",0,IFERROR(VLOOKUP(A10,従業員マスタ!$A:$G,7,0)*F10*1.25,0))) | J10: 0 | K10: =IF(OR(A10="EMP008",A10="EMP009",A10="EMP010",A10="EMP011",A10="EMP012",A10="EMP016"),IFERROR(VLOOKUP(A10,従業員マスタ!$A:$G,7,0)*(VLOOKUP(A10,月次集計!$A:$G,7,0)*8+VLOOKUP(A10,月次集計!$A:$I,9,0)),0),0) | L10: =H10+I10+J10-K10 | M10: =IFERROR(VLOOKUP(A10,従業員マスタ!$A:$I,8,0),0) | N10: =IFERROR(VLOOKUP(A10,従業員マスタ!$A:$J,9,0),0) | O10: =IFERROR(ROUND(L10*VLOOKUP(A10,従業員マスタ!$A:$K,10,0),0),0) | P10: =IFERROR(VLOOKUP(A10,従業員マスタ!$A:$L,11,0),0) | Q10: =L10-M10-N10-O10-P10 | R10: =IFERROR(VLOOKUP(A10,従業員マスタ!$A:$L,12,0),0) | S10: =IFERROR(VLOOKUP(A10,従業員マスタ!$A:$M,13,0),0) | T10: 0 | U10: =Q10-R10-S10-T10
A11: EMP009 | B11: =IFERROR(VLOOKUP(A11,従業員マスタ!$A:$B,2,0),"") | C11: =IFERROR(VLOOKUP(A11,従業員マスタ!$A:$D,4,0),"") | D11: =IFERROR(VLOOKUP(A11,従業員マスタ!$A:$F,6,0),0) | E11: =IFERROR(VLOOKUP(A11,月次集計!$A:$C,3,0),0) | F11: =IFERROR(VLOOKUP(A11,月次集計!$A:$H,8,0),0) | G11: =IFERROR(VLOOKUP(A11,月次集計!$A:$E,5,0),0) | H11: =IF(C11="月給",D11,IF(C11="日給",D11*E11+IFERROR(VLOOKUP(A11,従業員マスタ!$A:$G,7,0),0)*G11*8,IF(C11="時給",IFERROR(VLOOKUP(A11,従業員マスタ!$A:$G,7,0)*(IFERROR(VLOOKUP(A11,月次集計!$A:$T,20,0),0)+G11*5),0),0))) | I11: =IF(OR(A11="EMP001",A11="EMP002"),0,IF(C11="時給",0,IFERROR(VLOOKUP(A11,従業員マスタ!$A:$G,7,0)*F11*1.25,0))) | J11: 0 | K11: =IF(OR(A11="EMP008",A11="EMP009",A11="EMP010",A11="EMP011",A11="EMP012",A11="EMP016"),IFERROR(VLOOKUP(A11,従業員マスタ!$A:$G,7,0)*(VLOOKUP(A11,月次集計!$A:$G,7,0)*8+VLOOKUP(A11,月次集計!$A:$I,9,0)),0),0) | L11: =H11+I11+J11-K11 | M11: =IFERROR(VLOOKUP(A11,従業員マスタ!$A:$I,8,0),0) | N11: =IFERROR(VLOOKUP(A11,従業員マスタ!$A:$J,9,0),0) | O11: =IFERROR(ROUND(L11*VLOOKUP(A11,従業員マスタ!$A:$K,10,0),0),0) | P11: =IFERROR(VLOOKUP(A11,従業員マスタ!$A:$L,11,0),0) | Q11: =L11-M11-N11-O11-P11 | R11: =IFERROR(VLOOKUP(A11,従業員マスタ!$A:$L,12,0),0) | S11: =IFERROR(VLOOKUP(A11,従業員マスタ!$A:$M,13,0),0) | T11: 0 | U11: =Q11-R11-S11-T11
A12: EMP010 | B12: =IFERROR(VLOOKUP(A12,従業員マスタ!$A:$B,2,0),"") | C12: =IFERROR(VLOOKUP(A12,従業員マスタ!$A:$D,4,0),"") | D12: =IFERROR(VLOOKUP(A12,従業員マスタ!$A:$F,6,0),0) | E12: =IFERROR(VLOOKUP(A12,月次集計!$A:$C,3,0),0) | F12: =IFERROR(VLOOKUP(A12,月次集計!$A:$H,8,0),0) | G12: =IFERROR(VLOOKUP(A12,月次集計!$A:$E,5,0),0) | H12: =IF(C12="月給",D12,IF(C12="日給",D12*E12+IFERROR(VLOOKUP(A12,従業員マスタ!$A:$G,7,0),0)*G12*8,IF(C12="時給",IFERROR(VLOOKUP(A12,従業員マスタ!$A:$G,7,0)*(IFERROR(VLOOKUP(A12,月次集計!$A:$T,20,0),0)+G12*5),0),0))) | I12: =IF(OR(A12="EMP001",A12="EMP002"),0,IF(C12="時給",0,IFERROR(VLOOKUP(A12,従業員マスタ!$A:$G,7,0)*F12*1.25,0))) | J12: 0 | K12: =IF(OR(A12="EMP008",A12="EMP009",A12="EMP010",A12="EMP011",A12="EMP012",A12="EMP016"),IFERROR(VLOOKUP(A12,従業員マスタ!$A:$G,7,0)*(VLOOKUP(A12,月次集計!$A:$G,7,0)*8+VLOOKUP(A12,月次集計!$A:$I,9,0)),0),0) | L12: =H12+I12+J12-K12 | M12: =IFERROR(VLOOKUP(A12,従業員マスタ!$A:$I,8,0),0) | N12: =IFERROR(VLOOKUP(A12,従業員マスタ!$A:$J,9,0),0) | O12: =IFERROR(ROUND(L12*VLOOKUP(A12,従業員マスタ!$A:$K,10,0),0),0) | P12: =IFERROR(VLOOKUP(A12,従業員マスタ!$A:$L,11,0),0) | Q12: =L12-M12-N12-O12-P12 | R12: =IFERROR(VLOOKUP(A12,従業員マスタ!$A:$L,12,0),0) | S12: =IFERROR(VLOOKUP(A12,従業員マスタ!$A:$M,13,0),0) | T12: 0 | U12: =Q12-R12-S12-T12
A13: EMP011 | B13: =IFERROR(VLOOKUP(A13,従業員マスタ!$A:$B,2,0),"") | C13: =IFERROR(VLOOKUP(A13,従業員マスタ!$A:$D,4,0),"") | D13: =IFERROR(VLOOKUP(A13,従業員マスタ!$A:$F,6,0),0) | E13: =IFERROR(VLOOKUP(A13,月次集計!$A:$C,3,0),0) | F13: =IFERROR(VLOOKUP(A13,月次集計!$A:$H,8,0),0) | G13: =IFERROR(VLOOKUP(A13,月次集計!$A:$E,5,0),0) | H13: =IF(C13="月給",D13,IF(C13="日給",D13*E13+IFERROR(VLOOKUP(A13,従業員マスタ!$A:$G,7,0),0)*G13*8,IF(C13="時給",IFERROR(VLOOKUP(A13,従業員マスタ!$A:$G,7,0)*(IFERROR(VLOOKUP(A13,月次集計!$A:$T,20,0),0)+G13*5),0),0))) | I13: =IF(OR(A13="EMP001",A13="EMP002"),0,IF(C13="時給",0,IFERROR(VLOOKUP(A13,従業員マスタ!$A:$G,7,0)*F13*1.25,0))) | J13: 0 | K13: =IF(OR(A13="EMP008",A13="EMP009",A13="EMP010",A13="EMP011",A13="EMP012",A13="EMP016"),IFERROR(VLOOKUP(A13,従業員マスタ!$A:$G,7,0)*(VLOOKUP(A13,月次集計!$A:$G,7,0)*8+VLOOKUP(A13,月次集計!$A:$I,9,0)),0),0) | L13: =H13+I13+J13-K13 | M13: =IFERROR(VLOOKUP(A13,従業員マスタ!$A:$I,8,0),0) | N13: =IFERROR(VLOOKUP(A13,従業員マスタ!$A:$J,9,0),0) | O13: =IFERROR(ROUND(L13*VLOOKUP(A13,従業員マスタ!$A:$K,10,0),0),0) | P13: =IFERROR(VLOOKUP(A13,従業員マスタ!$A:$L,11,0),0) | Q13: =L13-M13-N13-O13-P13 | R13: =IFERROR(VLOOKUP(A13,従業員マスタ!$A:$L,12,0),0) | S13: =IFERROR(VLOOKUP(A13,従業員マスタ!$A:$M,13,0),0) | T13: 0 | U13: =Q13-R13-S13-T13
